<sdf version='1.6'>
  <world name='default'>
    <model name='ground_plane'>
      <static>1</static>
      <link name='link'>
        <collision name='collision'>
          <geometry>
            <plane>
              <normal>0 0 1</normal>
              <size>100 100</size>
            </plane>
          </geometry>
          <surface>
            <friction>
              <ode>
                <mu>100</mu>
                <mu2>50</mu2>
              </ode>
              <torsional>
                <ode/>
              </torsional>
            </friction>
            <contact>
              <ode/>
            </contact>
            <bounce/>
          </surface>
          <max_contacts>10</max_contacts>
        </collision>
        <visual name='visual'>
          <cast_shadows>0</cast_shadows>
          <geometry>
            <plane>
              <normal>0 0 1</normal>
              <size>100 100</size>
            </plane>
          </geometry>
          <material>
            <script>
              <uri>file://media/materials/scripts/gazebo.material</uri>
              <name>Gazebo/Grey</name>
            </script>
          </material>
        </visual>
        <self_collide>0</self_collide>
        <kinematic>0</kinematic>
        <gravity>1</gravity>
      </link>
    </model>
    <light name='sun' type='directional'>
      <cast_shadows>1</cast_shadows>
      <pose frame=''>0 0 10 0 -0 0</pose>
      <diffuse>0.8 0.8 0.8 1</diffuse>
      <specular>0.1 0.1 0.1 1</specular>
      <attenuation>
        <range>1000</range>
        <constant>0.9</constant>
        <linear>0.01</linear>
        <quadratic>0.001</quadratic>
      </attenuation>
      <direction>-0.5 0.5 -1</direction>
    </light>
    <model name='test_zone'>
      <link name='link'>
        <inertial>
          <mass>15</mass>
          <inertia>
            <ixx>0</ixx>
            <ixy>0</ixy>
            <ixz>0</ixz>
            <iyy>0</iyy>
            <iyz>0</iyz>
            <izz>0.1</izz>
          </inertia>
        </inertial>
        <collision name='collision'>
          <pose frame=''>-8.12 8.8 0 1.57 -0 0</pose>
          <geometry>
            <mesh>
              <uri>model://test_zone/meshes/building.dae</uri>
              <scale>1 1 1</scale>
            </mesh>
          </geometry>
          <max_contacts>10</max_contacts>
          <surface>
            <contact>
              <ode/>
            </contact>
            <bounce/>
            <friction>
              <torsional>
                <ode/>
              </torsional>
              <ode/>
            </friction>
          </surface>
        </collision>
        <visual name='visual'>
          <pose frame=''>-8.12 8.8 0 1.57 -0 0</pose>
          <geometry>
            <mesh>
              <uri>model://test_zone/meshes/building.dae</uri>
              <scale>1 1 1</scale>
            </mesh>
          </geometry>
        </visual>
        <self_collide>0</self_collide>
        <kinematic>0</kinematic>
        <gravity>1</gravity>
      </link>
      <static>1</static>
    </model>
    <model name='table1'>
      <static>1</static>
      <link name='link'>
        <collision name='surface'>
          <pose frame=''>0 0 0.755 0 -0 0</pose>
          <geometry>
            <box>
              <size>0.913 0.913 0.04</size>
            </box>
          </geometry>
          <max_contacts>10</max_contacts>
          <surface>
            <contact>
              <ode/>
            </contact>
            <bounce/>
            <friction>
              <torsional>
                <ode/>
              </torsional>
              <ode/>
            </friction>
          </surface>
        </collision>
        <collision name='column'>
          <pose frame=''>0 0 0.37 0 -0 0</pose>
          <geometry>
            <box>
              <size>0.042 0.042 0.74</size>
            </box>
          </geometry>
          <max_contacts>10</max_contacts>
          <surface>
            <contact>
              <ode/>
            </contact>
            <bounce/>
            <friction>
              <torsional>
                <ode/>
              </torsional>
              <ode/>
            </friction>
          </surface>
        </collision>
        <collision name='base'>
          <pose frame=''>0 0 0.02 0 -0 0</pose>
          <geometry>
            <box>
              <size>0.56 0.56 0.04</size>
            </box>
          </geometry>
          <max_contacts>10</max_contacts>
          <surface>
            <contact>
              <ode/>
            </contact>
            <bounce/>
            <friction>
              <torsional>
                <ode/>
              </torsional>
              <ode/>
            </friction>
          </surface>
        </collision>
        <visual name='visual'>
          <geometry>
            <mesh>
              <uri>model://cafe_table/meshes/cafe_table.dae</uri>
              <scale>1 1 1</scale>
            </mesh>
          </geometry>
        </visual>
        <self_collide>0</self_collide>
        <kinematic>0</kinematic>
        <gravity>1</gravity>
      </link>
      <pose frame=''>1 0 -0.08 0 -0 0</pose>
    </model>
    <model name='table2'>
      <static>1</static>
      <link name='link'>
        <collision name='surface'>
          <pose frame=''>0 0 0.755 0 -0 0</pose>
          <geometry>
            <box>
              <size>0.913 0.913 0.04</size>
            </box>
          </geometry>
          <max_contacts>10</max_contacts>
          <surface>
            <contact>
              <ode/>
            </contact>
            <bounce/>
            <friction>
              <torsional>
                <ode/>
              </torsional>
              <ode/>
            </friction>
          </surface>
        </collision>
        <collision name='column'>
          <pose frame=''>0 0 0.37 0 -0 0</pose>
          <geometry>
            <box>
              <size>0.042 0.042 0.74</size>
            </box>
          </geometry>
          <max_contacts>10</max_contacts>
          <surface>
            <contact>
              <ode/>
            </contact>
            <bounce/>
            <friction>
              <torsional>
                <ode/>
              </torsional>
              <ode/>
            </friction>
          </surface>
        </collision>
        <collision name='base'>
          <pose frame=''>0 0 0.02 0 -0 0</pose>
          <geometry>
            <box>
              <size>0.56 0.56 0.04</size>
            </box>
          </geometry>
          <max_contacts>10</max_contacts>
          <surface>
            <contact>
              <ode/>
            </contact>
            <bounce/>
            <friction>
              <torsional>
                <ode/>
              </torsional>
              <ode/>
            </friction>
          </surface>
        </collision>
        <visual name='visual'>
          <geometry>
            <mesh>
              <uri>model://cafe_table/meshes/cafe_table.dae</uri>
              <scale>1 1 1</scale>
            </mesh>
          </geometry>
        </visual>
        <self_collide>0</self_collide>
        <kinematic>0</kinematic>
        <gravity>1</gravity>
      </link>
      <pose frame=''>-3 5 0 0 -0 1.57</pose>
    </model>
    <model name='demo_cube'>
      <static>0</static>
      <link name='link'>
        <inertial>
          <mass>0.25</mass>
          <inertia>
            <ixx>0.001</ixx>
            <ixy>0</ixy>
            <ixz>0</ixz>
            <iyy>0.001</iyy>
            <iyz>0</iyz>
            <izz>0.001</izz>
          </inertia>
        </inertial>
        <collision name='collision'>
          <geometry>
            <box>
              <size>0.06 0.06 0.06</size>
            </box>
          </geometry>
          <surface>
            <friction>
              <ode>
                <mu>30</mu>
                <mu2>30</mu2>
              </ode>
              <torsional>
                <ode/>
              </torsional>
            </friction>
            <contact>
              <ode>
                <kp>1e+06</kp>
                <kd>100</kd>
                <max_vel>1</max_vel>
                <min_depth>0.002</min_depth>
              </ode>
            </contact>
            <bounce/>
          </surface>
          <max_contacts>10</max_contacts>
        </collision>
        <visual name='visual'>
          <geometry>
            <box>
              <size>0.06 0.06 0.06</size>
            </box>
          </geometry>
          <material>
            <script>
              <uri>file://media/materials/scripts/gazebo.material</uri>
              <name>Gazebo/Blue</name>
            </script>
          </material>
        </visual>
        <velocity_decay>
          <linear>0</linear>
          <angular>0</angular>
        </velocity_decay>
        <self_collide>0</self_collide>
        <kinematic>0</kinematic>
        <gravity>1</gravity>
      </link>
      <pose frame=''>0.8 0.1 0.75 0 -0 0</pose>
    </model>
    <gravity>0 0 -9.8</gravity>
    <magnetic_field>6e-06 2.3e-05 -4.2e-05</magnetic_field>
    <atmosphere type='adiabatic'/>
    <physics name='default_physics' default='0' type='ode'>
      <max_step_size>0.001</max_step_size>
      <real_time_factor>1</real_time_factor>
      <real_time_update_rate>1000</real_time_update_rate>
    </physics>
    <scene>
      <ambient>0.4 0.4 0.4 1</ambient>
      <background>0.7 0.7 0.7 1</background>
      <shadows>1</shadows>
    </scene>
    <spherical_coordinates>
      <surface_model>EARTH_WGS84</surface_model>
      <latitude_deg>0</latitude_deg>
      <longitude_deg>0</longitude_deg>
      <elevation>0</elevation>
      <heading_deg>0</heading_deg>
    </spherical_coordinates>
    <model name='fetch'>
      <link name='base_link'>
        <pose frame=''>0 0 0 0 -0 0</pose>
        <inertial>
          <pose frame=''>-0.028329 0.000913 0.103558 0 -0 0</pose>
          <mass>83.4172</mass>
          <inertia>
            <ixx>6.20776</ixx>
            <ixy>0.0213393</ixy>
            <ixz>1.10946</ixz>
            <iyy>6.49062</iyy>
            <iyz>-0.0326202</iyz>
            <izz>1.3596</izz>
          </inertia>
        </inertial>
        <collision name='base_link_collision'>
          <pose frame=''>0 0 0 0 -0 0</pose>
          <geometry>
            <mesh>
              <scale>1 1 1</scale>
              <uri>/home/fitter/catkin_ws/src/fetch_ros/fetch_description/meshes/base_link_collision.STL</uri>
            </mesh>
          </geometry>
          <surface>
            <contact>
              <ode>
                <kp>1e+08</kp>
                <kd>10</kd>
                <max_vel>10</max_vel>
                <min_depth>0.0005</min_depth>
              </ode>
            </contact>
            <friction>
              <ode>
                <mu>0.1</mu>
                <mu2>0.1</mu2>
                <fdir1>1 0 0</fdir1>
              </ode>
              <torsional>
                <ode/>
              </torsional>
            </friction>
            <bounce/>
          </surface>
          <max_contacts>10</max_contacts>
        </collision>
        <collision name='base_link_fixed_joint_lump__estop_link_collision_1'>
          <pose frame=''>-0.12465 0.23892 0.31127 1.5708 -0 0</pose>
          <geometry>
            <mesh>
              <scale>1 1 1</scale>
              <uri>/home/fitter/catkin_ws/src/fetch_ros/fetch_description/meshes/estop_link.STL</uri>
            </mesh>
          </geometry>
          <surface>
            <contact>
              <ode/>
            </contact>
            <friction>
              <ode/>
              <torsional>
                <ode/>
              </torsional>
            </friction>
            <bounce/>
          </surface>
          <max_contacts>10</max_contacts>
        </collision>
        <collision name='base_link_fixed_joint_lump__laser_link_collision_2'>
          <pose frame=''>0.235 0 0.2878 -3.14159 -0 0</pose>
          <geometry>
            <mesh>
              <scale>1 1 1</scale>
              <uri>/home/fitter/catkin_ws/src/fetch_ros/fetch_description/meshes/laser_link.STL</uri>
            </mesh>
          </geometry>
          <surface>
            <contact>
              <ode/>
            </contact>
            <friction>
              <ode/>
              <torsional>
                <ode/>
              </torsional>
            </friction>
            <bounce/>
          </surface>
          <max_contacts>10</max_contacts>
        </collision>
        <collision name='base_link_fixed_joint_lump__torso_fixed_link_collision_3'>
          <pose frame=''>-0.086875 0 0.377425 0 -0 0</pose>
          <geometry>
            <mesh>
              <scale>1 1 1</scale>
              <uri>/home/fitter/catkin_ws/src/fetch_ros/fetch_description/meshes/torso_fixed_link.STL</uri>
            </mesh>
          </geometry>
          <max_contacts>10</max_contacts>
          <surface>
            <contact>
              <ode/>
            </contact>
            <bounce/>
            <friction>
              <torsional>
                <ode/>
              </torsional>
              <ode/>
            </friction>
          </surface>
        </collision>
        <visual name='base_link_visual'>
          <pose frame=''>0 0 0 0 -0 0</pose>
          <geometry>
            <mesh>
              <scale>1 1 1</scale>
              <uri>/home/fitter/catkin_ws/src/fetch_ros/fetch_description/meshes/base_link.dae</uri>
            </mesh>
          </geometry>
          <material>
            <script>
              <uri>__default__</uri>
              <name>__default__</name>
            </script>
          </material>
        </visual>
        <visual name='base_link_fixed_joint_lump__estop_link_visual_1'>
          <pose frame=''>-0.12465 0.23892 0.31127 1.5708 -0 0</pose>
          <geometry>
            <mesh>
              <scale>1 1 1</scale>
              <uri>/home/fitter/catkin_ws/src/fetch_ros/fetch_description/meshes/estop_link.STL</uri>
            </mesh>
          </geometry>
          <material>
            <script>
              <name>Gazebo/Red</name>
              <uri>file://media/materials/scripts/gazebo.material</uri>
            </script>
          </material>
        </visual>
        <visual name='base_link_fixed_joint_lump__laser_link_visual_2'>
          <pose frame=''>0.235 0 0.2878 -3.14159 -0 0</pose>
          <geometry>
            <mesh>
              <scale>1 1 1</scale>
              <uri>/home/fitter/catkin_ws/src/fetch_ros/fetch_description/meshes/laser_link.STL</uri>
            </mesh>
          </geometry>
          <material>
            <script>
              <uri>__default__</uri>
              <name>__default__</name>
            </script>
          </material>
        </visual>
        <visual name='base_link_fixed_joint_lump__torso_fixed_link_visual_3'>
          <pose frame=''>-0.086875 0 0.377425 0 -0 0</pose>
          <geometry>
            <mesh>
              <scale>1 1 1</scale>
              <uri>/home/fitter/catkin_ws/src/fetch_ros/fetch_description/meshes/torso_fixed_link.dae</uri>
            </mesh>
          </geometry>
        </visual>
        <velocity_decay/>
        <velocity_decay/>
        <gravity>1</gravity>
        <velocity_decay/>
        <self_collide>0</self_collide>
        <sensor name='base_laser' type='ray'>
          <visualize>0</visualize>
          <update_rate>15</update_rate>
          <ray>
            <scan>
              <horizontal>
                <samples>662</samples>
                <resolution>1</resolution>
                <min_angle>-1.91986</min_angle>
                <max_angle>1.91986</max_angle>
              </horizontal>
              <vertical>
                <samples>1</samples>
                <min_angle>0</min_angle>
                <max_angle>0</max_angle>
              </vertical>
            </scan>
            <range>
              <min>0.05</min>
              <max>25</max>
              <resolution>0.01</resolution>
            </range>
            <noise>
              <type>gaussian</type>
              <mean>0</mean>
              <stddev>0.02</stddev>
            </noise>
          </ray>
          <plugin name='gazebo_ros_base_hokuyo_controller' filename='libgazebo_ros_laser.so'>
            <topicName>/base_scan</topicName>
            <frameName>laser_link</frameName>
            <robotNamespace>/</robotNamespace>
          </plugin>
          <pose frame=''>0.235 0 0.2878 -3.14159 -0 0</pose>
        </sensor>
        <kinematic>0</kinematic>
      </link>
      <link name='l_wheel_link'>
        <pose frame=''>0.001291 0.18738 0.055325 0 -0 0</pose>
        <inertial>
          <pose frame=''>0 0 0 0 -0 0</pose>
          <mass>4.3542</mass>
          <inertia>
            <ixx>0.0045</ixx>
            <ixy>0</ixy>
            <ixz>0</ixz>
            <iyy>0.005</iyy>
            <iyz>0</iyz>
            <izz>0.0045</izz>
          </inertia>
        </inertial>
        <collision name='l_wheel_link_collision'>
          <pose frame=''>0 0 0 0 -0 0</pose>
          <geometry>
            <mesh>
              <scale>1 1 1</scale>
              <uri>/home/fitter/catkin_ws/src/fetch_ros/fetch_description/meshes/l_wheel_link_collision.STL</uri>
            </mesh>
          </geometry>
          <surface>
            <contact>
              <ode>
                <kp>500000</kp>
                <kd>10</kd>
                <max_vel>1</max_vel>
                <min_depth>0.003</min_depth>
              </ode>
            </contact>
            <friction>
              <ode>
                <mu>10</mu>
                <mu2>10</mu2>
                <fdir1>1 0 0</fdir1>
              </ode>
              <torsional>
                <ode/>
              </torsional>
            </friction>
            <bounce/>
          </surface>
          <max_contacts>10</max_contacts>
        </collision>
        <visual name='l_wheel_link_visual'>
          <pose frame=''>0 0 0 0 -0 0</pose>
          <geometry>
            <mesh>
              <scale>1 1 1</scale>
              <uri>/home/fitter/catkin_ws/src/fetch_ros/fetch_description/meshes/l_wheel_link.STL</uri>
            </mesh>
          </geometry>
          <material>
            <script>
              <name>Gazebo/Black</name>
              <uri>file://media/materials/scripts/gazebo.material</uri>
            </script>
          </material>
        </visual>
        <gravity>1</gravity>
        <velocity_decay/>
        <self_collide>0</self_collide>
        <kinematic>0</kinematic>
      </link>
      <joint name='l_wheel_joint' type='revolute'>
        <child>l_wheel_link</child>
        <parent>base_link</parent>
        <axis>
          <xyz>0 1 0</xyz>
          <limit>
            <lower>-1e+16</lower>
            <upper>1e+16</upper>
          </limit>
          <dynamics>
            <spring_reference>0</spring_reference>
            <spring_stiffness>0</spring_stiffness>
          </dynamics>
          <use_parent_model_frame>1</use_parent_model_frame>
        </axis>
        <physics>
          <ode>
            <implicit_spring_damper>1</implicit_spring_damper>
            <cfm_damping>1</cfm_damping>
            <limit>
              <cfm>0</cfm>
              <erp>0.2</erp>
            </limit>
          </ode>
        </physics>
      </joint>
      <link name='r_wheel_link'>
        <pose frame=''>0.001291 -0.18738 0.055325 0 -0 0</pose>
        <inertial>
          <pose frame=''>0 0 0 0 -0 0</pose>
          <mass>4.3542</mass>
          <inertia>
            <ixx>0.0045</ixx>
            <ixy>0</ixy>
            <ixz>0</ixz>
            <iyy>0.005</iyy>
            <iyz>0</iyz>
            <izz>0.0045</izz>
          </inertia>
        </inertial>
        <collision name='r_wheel_link_collision'>
          <pose frame=''>0 0 0 0 -0 0</pose>
          <geometry>
            <mesh>
              <scale>1 1 1</scale>
              <uri>/home/fitter/catkin_ws/src/fetch_ros/fetch_description/meshes/r_wheel_link_collision.STL</uri>
            </mesh>
          </geometry>
          <surface>
            <contact>
              <ode>
                <kp>500000</kp>
                <kd>10</kd>
                <max_vel>1</max_vel>
                <min_depth>0.003</min_depth>
              </ode>
            </contact>
            <friction>
              <ode>
                <mu>10</mu>
                <mu2>10</mu2>
                <fdir1>1 0 0</fdir1>
              </ode>
              <torsional>
                <ode/>
              </torsional>
            </friction>
            <bounce/>
          </surface>
          <max_contacts>10</max_contacts>
        </collision>
        <visual name='r_wheel_link_visual'>
          <pose frame=''>0 0 0 0 -0 0</pose>
          <geometry>
            <mesh>
              <scale>1 1 1</scale>
              <uri>/home/fitter/catkin_ws/src/fetch_ros/fetch_description/meshes/r_wheel_link.STL</uri>
            </mesh>
          </geometry>
          <material>
            <script>
              <name>Gazebo/Black</name>
              <uri>file://media/materials/scripts/gazebo.material</uri>
            </script>
          </material>
        </visual>
        <gravity>1</gravity>
        <velocity_decay/>
        <self_collide>0</self_collide>
        <kinematic>0</kinematic>
      </link>
      <joint name='r_wheel_joint' type='revolute'>
        <child>r_wheel_link</child>
        <parent>base_link</parent>
        <axis>
          <xyz>0 1 0</xyz>
          <limit>
            <lower>-1e+16</lower>
            <upper>1e+16</upper>
          </limit>
          <dynamics>
            <spring_reference>0</spring_reference>
            <spring_stiffness>0</spring_stiffness>
          </dynamics>
          <use_parent_model_frame>1</use_parent_model_frame>
        </axis>
        <physics>
          <ode>
            <implicit_spring_damper>1</implicit_spring_damper>
            <cfm_damping>1</cfm_damping>
            <limit>
              <cfm>0</cfm>
              <erp>0.2</erp>
            </limit>
          </ode>
        </physics>
      </joint>
      <link name='torso_lift_link'>
        <pose frame=''>-0.086875 0 0.37743 0 -0 0</pose>
        <inertial>
          <pose frame=''>-0.000984 -0.000886 0.286874 0 -0 0</pose>
          <mass>10.949</mass>
          <inertia>
            <ixx>0.36931</ixx>
            <ixy>-3.0664e-06</ixy>
            <ixz>-0.0147406</ixz>
            <iyy>0.367812</iyy>
            <iyz>-0.000535712</iyz>
            <izz>0.0971639</izz>
          </inertia>
        </inertial>
        <collision name='torso_lift_link_collision'>
          <pose frame=''>0 0 0 0 -0 0</pose>
          <geometry>
            <mesh>
              <scale>1 1 1</scale>
              <uri>/home/fitter/catkin_ws/src/fetch_ros/fetch_description/meshes/torso_lift_link_collision.STL</uri>
            </mesh>
          </geometry>
          <max_contacts>10</max_contacts>
          <surface>
            <contact>
              <ode/>
            </contact>
            <bounce/>
            <friction>
              <torsional>
                <ode/>
              </torsional>
              <ode/>
            </friction>
          </surface>
        </collision>
        <collision name='torso_lift_link_fixed_joint_lump__bellows_link2_collision_1'>
          <pose frame=''>0 0 0 0 -0 0</pose>
          <geometry>
            <mesh>
              <scale>1 1 1</scale>
              <uri>/home/fitter/catkin_ws/src/fetch_ros/fetch_description/meshes/bellows_link_collision.STL</uri>
            </mesh>
          </geometry>
          <surface>
            <contact>
              <ode/>
            </contact>
            <friction>
              <ode/>
              <torsional>
                <ode/>
              </torsional>
            </friction>
            <bounce/>
          </surface>
          <max_contacts>10</max_contacts>
        </collision>
        <visual name='torso_lift_link_visual'>
          <pose frame=''>0 0 0 0 -0 0</pose>
          <geometry>
            <mesh>
              <scale>1 1 1</scale>
              <uri>/home/fitter/catkin_ws/src/fetch_ros/fetch_description/meshes/torso_lift_link.dae</uri>
            </mesh>
          </geometry>
        </visual>
        <visual name='torso_lift_link_fixed_joint_lump__bellows_link2_visual_1'>
          <pose frame=''>0 0 0 0 -0 0</pose>
          <geometry>
            <mesh>
              <scale>1 1 1</scale>
              <uri>/home/fitter/catkin_ws/src/fetch_ros/fetch_description/meshes/bellows_link.STL</uri>
            </mesh>
          </geometry>
          <material>
            <script>
              <name>Gazebo/Black</name>
              <uri>file://media/materials/scripts/gazebo.material</uri>
            </script>
          </material>
        </visual>
        <gravity>1</gravity>
        <velocity_decay/>
        <self_collide>0</self_collide>
        <kinematic>0</kinematic>
      </link>
      <joint name='torso_lift_joint' type='prismatic'>
        <child>torso_lift_link</child>
        <parent>base_link</parent>
        <axis>
          <xyz>0 0 1</xyz>
          <limit>
            <lower>0</lower>
            <upper>0.38615</upper>
            <effort>450</effort>
            <velocity>0.1</velocity>
          </limit>
          <dynamics>
            <damping>100</damping>
            <friction>0</friction>
            <spring_reference>0</spring_reference>
            <spring_stiffness>0</spring_stiffness>
          </dynamics>
          <use_parent_model_frame>1</use_parent_model_frame>
        </axis>
      </joint>
      <link name='bellows_link'>
        <pose frame=''>-0.086875 0 0.37743 0 -0 0</pose>
        <inertial>
          <pose frame=''>0.019132 -0 -0.134862 0 -0 0</pose>
          <mass>0.169374</mass>
          <inertia>
            <ixx>0.00331159</ixx>
            <ixy>-8.9231e-18</ixy>
            <ixz>-5.38622e-08</ixz>
            <iyy>0.00174447</iyy>
            <iyz>-8.06965e-17</iyz>
            <izz>0.00169418</izz>
          </inertia>
        </inertial>
        <collision name='bellows_link_collision'>
          <pose frame=''>0 0 0 0 -0 0</pose>
          <geometry>
            <mesh>
              <scale>1 1 1</scale>
              <uri>/home/fitter/catkin_ws/src/fetch_ros/fetch_description/meshes/bellows_link_collision.STL</uri>
            </mesh>
          </geometry>
          <surface>
            <contact>
              <ode/>
            </contact>
            <friction>
              <ode/>
              <torsional>
                <ode/>
              </torsional>
            </friction>
            <bounce/>
          </surface>
          <max_contacts>10</max_contacts>
        </collision>
        <visual name='bellows_link_visual'>
          <pose frame=''>0 0 0 0 -0 0</pose>
          <geometry>
            <mesh>
              <scale>1 1 1</scale>
              <uri>/home/fitter/catkin_ws/src/fetch_ros/fetch_description/meshes/bellows_link.STL</uri>
            </mesh>
          </geometry>
          <material>
            <script>
              <name>Gazebo/Black</name>
              <uri>file://media/materials/scripts/gazebo.material</uri>
            </script>
          </material>
        </visual>
        <gravity>1</gravity>
        <velocity_decay/>
        <self_collide>0</self_collide>
        <kinematic>0</kinematic>
      </link>
      <joint name='bellows_joint' type='prismatic'>
        <child>bellows_link</child>
        <parent>torso_lift_link</parent>
        <axis>
          <xyz>0 -0 -1</xyz>
          <limit>
            <lower>0</lower>
            <upper>0.4</upper>
            <effort>5</effort>
            <velocity>0.1</velocity>
          </limit>
          <dynamics>
            <spring_reference>0</spring_reference>
            <spring_stiffness>0</spring_stiffness>
          </dynamics>
          <use_parent_model_frame>1</use_parent_model_frame>
        </axis>
      </joint>
      <link name='head_pan_link'>
        <pose frame=''>-0.03375 0 0.980431 0 -0 0</pose>
        <inertial>
          <pose frame=''>0.0321 0.0161 0.039 0 -0 0</pose>
          <mass>2.2556</mass>
          <inertia>
            <ixx>0.0129</ixx>
            <ixy>0.0002</ixy>
            <ixz>0.0007</ixz>
            <iyy>0.0095</iyy>
            <iyz>-0</iyz>
            <izz>0.0184</izz>
          </inertia>
        </inertial>
        <collision name='head_pan_link_collision'>
          <pose frame=''>0 0 0 0 -0 0</pose>
          <geometry>
            <mesh>
              <scale>1 1 1</scale>
              <uri>/home/fitter/catkin_ws/src/fetch_ros/fetch_description/meshes/head_pan_link_collision.STL</uri>
            </mesh>
          </geometry>
          <max_contacts>10</max_contacts>
          <surface>
            <contact>
              <ode/>
            </contact>
            <bounce/>
            <friction>
              <torsional>
                <ode/>
              </torsional>
              <ode/>
            </friction>
          </surface>
        </collision>
        <visual name='head_pan_link_visual'>
          <pose frame=''>0 0 0 0 -0 0</pose>
          <geometry>
            <mesh>
              <scale>1 1 1</scale>
              <uri>/home/fitter/catkin_ws/src/fetch_ros/fetch_description/meshes/head_pan_link.dae</uri>
            </mesh>
          </geometry>
        </visual>
        <self_collide>0</self_collide>
        <kinematic>0</kinematic>
        <gravity>1</gravity>
      </link>
      <joint name='head_pan_joint' type='revolute'>
        <child>head_pan_link</child>
        <parent>torso_lift_link</parent>
        <axis>
          <xyz>0 0 1</xyz>
          <limit>
            <lower>-1.57</lower>
            <upper>1.57</upper>
            <effort>0.32</effort>
            <velocity>1.57</velocity>
          </limit>
          <dynamics>
            <spring_reference>0</spring_reference>
            <spring_stiffness>0</spring_stiffness>
          </dynamics>
          <use_parent_model_frame>1</use_parent_model_frame>
        </axis>
      </joint>
      <link name='head_tilt_link'>
        <pose frame=''>0.10878 0 1.03843 0 -0 0</pose>
        <inertial>
          <pose frame=''>0.0081 0.0025 0.0113 0 -0 0</pose>
          <mass>0.9087</mass>
          <inertia>
            <ixx>0.0061</ixx>
            <ixy>-0</ixy>
            <ixz>0.0002</ixz>
            <iyy>0.0014</iyy>
            <iyz>-0.0001</iyz>
            <izz>0.0061</izz>
          </inertia>
        </inertial>
        <collision name='head_tilt_link_collision'>
          <pose frame=''>0 0 0 0 -0 0</pose>
          <geometry>
            <mesh>
              <scale>1 1 1</scale>
              <uri>/home/fitter/catkin_ws/src/fetch_ros/fetch_description/meshes/head_tilt_link_collision.STL</uri>
            </mesh>
          </geometry>
          <max_contacts>10</max_contacts>
          <surface>
            <contact>
              <ode/>
            </contact>
            <bounce/>
            <friction>
              <torsional>
                <ode/>
              </torsional>
              <ode/>
            </friction>
          </surface>
        </collision>
        <visual name='head_tilt_link_visual'>
          <pose frame=''>0 0 0 0 -0 0</pose>
          <geometry>
            <mesh>
              <scale>1 1 1</scale>
              <uri>/home/fitter/catkin_ws/src/fetch_ros/fetch_description/meshes/head_tilt_link.dae</uri>
            </mesh>
          </geometry>
        </visual>
        <gravity>1</gravity>
        <velocity_decay/>
        <self_collide>0</self_collide>
        <sensor name='camera' type='depth'>
          <always_on>1</always_on>
          <update_rate>15</update_rate>
          <camera name='__default__'>
            <horizontal_fov>1.0472</horizontal_fov>
            <image>
              <format>B8G8R8</format>
              <width>640</width>
              <height>480</height>
            </image>
            <clip>
              <near>0.05</near>
              <far>50</far>
            </clip>
          </camera>
          <plugin name='head_camera_controller' filename='libgazebo_ros_openni_kinect.so'>
            <baseline>0.1</baseline>
            <alwaysOn>true</alwaysOn>
            <updateRate>15.0</updateRate>
            <cameraName>head_camera</cameraName>
            <imageTopicName>/head_camera/rgb/image_raw</imageTopicName>
            <cameraInfoTopicName>/head_camera/rgb/camera_info</cameraInfoTopicName>
            <depthImageTopicName>/head_camera/depth_registered/image_raw</depthImageTopicName>
            <depthImageCameraInfoTopicName>/head_camera/depth_registered/camera_info</depthImageCameraInfoTopicName>
            <pointCloudTopicName>/head_camera/depth_registered/points</pointCloudTopicName>
            <frameName>head_camera_rgb_optical_frame</frameName>
            <pointCloudCutoff>0.35</pointCloudCutoff>
            <pointCloudCutoffMax>4.5</pointCloudCutoffMax>
            <CxPrime>0</CxPrime>
            <Cx>0</Cx>
            <Cy>0</Cy>
            <focalLength>0</focalLength>
            <hackBaseline>0</hackBaseline>
            <robotNamespace>/</robotNamespace>
          </plugin>
          <pose frame=''>0.055 0.02 0.0225 0 -0 0</pose>
        </sensor>
        <kinematic>0</kinematic>
      </link>
      <joint name='head_tilt_joint' type='revolute'>
        <child>head_tilt_link</child>
        <parent>head_pan_link</parent>
        <axis>
          <xyz>0 1 0</xyz>
          <limit>
            <lower>-0.76</lower>
            <upper>1.45</upper>
            <effort>0.68</effort>
            <velocity>1.57</velocity>
          </limit>
          <dynamics>
            <spring_reference>0</spring_reference>
            <spring_stiffness>0</spring_stiffness>
          </dynamics>
          <use_parent_model_frame>1</use_parent_model_frame>
        </axis>
      </joint>
      <link name='shoulder_pan_link'>
        <pose frame=''>0.03265 0 0.72601 0 -0 0</pose>
        <inertial>
          <pose frame=''>0.0927 -0.0056 0.0564 0 -0 0</pose>
          <mass>2.5587</mass>
          <inertia>
            <ixx>0.0043</ixx>
            <ixy>-0.0001</ixy>
            <ixz>0.001</ixz>
            <iyy>0.0087</iyy>
            <iyz>-0.0001</iyz>
            <izz>0.0087</izz>
          </inertia>
        </inertial>
        <collision name='shoulder_pan_link_collision'>
          <pose frame=''>0 0 0 0 -0 0</pose>
          <geometry>
            <mesh>
              <scale>1 1 1</scale>
              <uri>/home/fitter/catkin_ws/src/fetch_ros/fetch_description/meshes/shoulder_pan_link_collision.STL</uri>
            </mesh>
          </geometry>
          <max_contacts>10</max_contacts>
          <surface>
            <contact>
              <ode/>
            </contact>
            <bounce/>
            <friction>
              <torsional>
                <ode/>
              </torsional>
              <ode/>
            </friction>
          </surface>
        </collision>
        <visual name='shoulder_pan_link_visual'>
          <pose frame=''>0 0 0 0 -0 0</pose>
          <geometry>
            <mesh>
              <scale>1 1 1</scale>
              <uri>/home/fitter/catkin_ws/src/fetch_ros/fetch_description/meshes/shoulder_pan_link.dae</uri>
            </mesh>
          </geometry>
        </visual>
        <self_collide>0</self_collide>
        <kinematic>0</kinematic>
        <gravity>1</gravity>
      </link>
      <joint name='shoulder_pan_joint' type='revolute'>
        <child>shoulder_pan_link</child>
        <parent>torso_lift_link</parent>
        <axis>
          <xyz>0 0 1</xyz>
          <limit>
            <lower>-1.6056</lower>
            <upper>1.6056</upper>
            <effort>33.82</effort>
            <velocity>1.256</velocity>
          </limit>
          <dynamics>
            <damping>1</damping>
            <friction>0</friction>
            <spring_reference>0</spring_reference>
            <spring_stiffness>0</spring_stiffness>
          </dynamics>
          <use_parent_model_frame>1</use_parent_model_frame>
        </axis>
      </joint>
      <link name='shoulder_lift_link'>
        <pose frame=''>0.14965 0 0.78601 0 -0 0</pose>
        <inertial>
          <pose frame=''>0.1432 0.0072 -0.0001 0 -0 0</pose>
          <mass>2.6615</mass>
          <inertia>
            <ixx>0.0028</ixx>
            <ixy>-0.0021</ixy>
            <ixz>-0</ixz>
            <iyy>0.0111</iyy>
            <iyz>-0</iyz>
            <izz>0.0112</izz>
          </inertia>
        </inertial>
        <collision name='shoulder_lift_link_collision'>
          <pose frame=''>0 0 0 0 -0 0</pose>
          <geometry>
            <mesh>
              <scale>1 1 1</scale>
              <uri>/home/fitter/catkin_ws/src/fetch_ros/fetch_description/meshes/shoulder_lift_link_collision.STL</uri>
            </mesh>
          </geometry>
          <max_contacts>10</max_contacts>
          <surface>
            <contact>
              <ode/>
            </contact>
            <bounce/>
            <friction>
              <torsional>
                <ode/>
              </torsional>
              <ode/>
            </friction>
          </surface>
        </collision>
        <visual name='shoulder_lift_link_visual'>
          <pose frame=''>0 0 0 0 -0 0</pose>
          <geometry>
            <mesh>
              <scale>1 1 1</scale>
              <uri>/home/fitter/catkin_ws/src/fetch_ros/fetch_description/meshes/shoulder_lift_link.dae</uri>
            </mesh>
          </geometry>
        </visual>
        <self_collide>0</self_collide>
        <kinematic>0</kinematic>
        <gravity>1</gravity>
      </link>
      <joint name='shoulder_lift_joint' type='revolute'>
        <child>shoulder_lift_link</child>
        <parent>shoulder_pan_link</parent>
        <axis>
          <xyz>0 1 0</xyz>
          <limit>
            <lower>-1.221</lower>
            <upper>1.518</upper>
            <effort>131.76</effort>
            <velocity>1.454</velocity>
          </limit>
          <dynamics>
            <damping>1</damping>
            <friction>0</friction>
            <spring_reference>0</spring_reference>
            <spring_stiffness>0</spring_stiffness>
          </dynamics>
          <use_parent_model_frame>1</use_parent_model_frame>
        </axis>
      </joint>
      <link name='upperarm_roll_link'>
        <pose frame=''>0.36865 0 0.78601 0 -0 0</pose>
        <inertial>
          <pose frame=''>0.1165 0.0014 0 0 -0 0</pose>
          <mass>2.3311</mass>
          <inertia>
            <ixx>0.0019</ixx>
            <ixy>-0.0001</ixy>
            <ixz>0</ixz>
            <iyy>0.0045</iyy>
            <iyz>0</iyz>
            <izz>0.0047</izz>
          </inertia>
        </inertial>
        <collision name='upperarm_roll_link_collision'>
          <pose frame=''>0 0 0 0 -0 0</pose>
          <geometry>
            <mesh>
              <scale>1 1 1</scale>
              <uri>/home/fitter/catkin_ws/src/fetch_ros/fetch_description/meshes/upperarm_roll_link_collision.STL</uri>
            </mesh>
          </geometry>
          <max_contacts>10</max_contacts>
          <surface>
            <contact>
              <ode/>
            </contact>
            <bounce/>
            <friction>
              <torsional>
                <ode/>
              </torsional>
              <ode/>
            </friction>
          </surface>
        </collision>
        <visual name='upperarm_roll_link_visual'>
          <pose frame=''>0 0 0 0 -0 0</pose>
          <geometry>
            <mesh>
              <scale>1 1 1</scale>
              <uri>/home/fitter/catkin_ws/src/fetch_ros/fetch_description/meshes/upperarm_roll_link.dae</uri>
            </mesh>
          </geometry>
        </visual>
        <self_collide>0</self_collide>
        <kinematic>0</kinematic>
        <gravity>1</gravity>
      </link>
      <joint name='upperarm_roll_joint' type='revolute'>
        <child>upperarm_roll_link</child>
        <parent>shoulder_lift_link</parent>
        <axis>
          <xyz>1 0 0</xyz>
          <limit>
            <lower>-1e+16</lower>
            <upper>1e+16</upper>
          </limit>
          <dynamics>
            <damping>5</damping>
            <friction>0</friction>
            <spring_reference>0</spring_reference>
            <spring_stiffness>0</spring_stiffness>
          </dynamics>
          <use_parent_model_frame>1</use_parent_model_frame>
        </axis>
      </joint>
      <link name='elbow_flex_link'>
        <pose frame=''>0.50165 0 0.78601 0 -0 0</pose>
        <inertial>
          <pose frame=''>0.1279 0.0073 0 0 -0 0</pose>
          <mass>2.1299</mass>
          <inertia>
            <ixx>0.0024</ixx>
            <ixy>-0.0016</ixy>
            <ixz>0</ixz>
            <iyy>0.0082</iyy>
            <iyz>-0</iyz>
            <izz>0.0084</izz>
          </inertia>
        </inertial>
        <collision name='elbow_flex_link_collision'>
          <pose frame=''>0 0 0 0 -0 0</pose>
          <geometry>
            <mesh>
              <scale>1 1 1</scale>
              <uri>/home/fitter/catkin_ws/src/fetch_ros/fetch_description/meshes/elbow_flex_link_collision.STL</uri>
            </mesh>
          </geometry>
          <max_contacts>10</max_contacts>
          <surface>
            <contact>
              <ode/>
            </contact>
            <bounce/>
            <friction>
              <torsional>
                <ode/>
              </torsional>
              <ode/>
            </friction>
          </surface>
        </collision>
        <visual name='elbow_flex_link_visual'>
          <pose frame=''>0 0 0 0 -0 0</pose>
          <geometry>
            <mesh>
              <scale>1 1 1</scale>
              <uri>/home/fitter/catkin_ws/src/fetch_ros/fetch_description/meshes/elbow_flex_link.dae</uri>
            </mesh>
          </geometry>
        </visual>
        <self_collide>0</self_collide>
        <kinematic>0</kinematic>
        <gravity>1</gravity>
      </link>
      <joint name='elbow_flex_joint' type='revolute'>
        <child>elbow_flex_link</child>
        <parent>upperarm_roll_link</parent>
        <axis>
          <xyz>0 1 0</xyz>
          <limit>
            <lower>-2.251</lower>
            <upper>2.251</upper>
            <effort>66.18</effort>
            <velocity>1.521</velocity>
          </limit>
          <dynamics>
            <damping>1</damping>
            <friction>0</friction>
            <spring_reference>0</spring_reference>
            <spring_stiffness>0</spring_stiffness>
          </dynamics>
          <use_parent_model_frame>1</use_parent_model_frame>
        </axis>
      </joint>
      <link name='forearm_roll_link'>
        <pose frame=''>0.69865 0 0.78601 0 -0 0</pose>
        <inertial>
          <pose frame=''>0.1097 -0.0266 0 0 -0 0</pose>
          <mass>1.6563</mass>
          <inertia>
            <ixx>0.0016</ixx>
            <ixy>-0.0003</ixy>
            <ixz>0</ixz>
            <iyy>0.003</iyy>
            <iyz>-0</iyz>
            <izz>0.0035</izz>
          </inertia>
        </inertial>
        <collision name='forearm_roll_link_collision'>
          <pose frame=''>0 0 0 0 -0 0</pose>
          <geometry>
            <mesh>
              <scale>1 1 1</scale>
              <uri>/home/fitter/catkin_ws/src/fetch_ros/fetch_description/meshes/forearm_roll_link_collision.STL</uri>
            </mesh>
          </geometry>
          <max_contacts>10</max_contacts>
          <surface>
            <contact>
              <ode/>
            </contact>
            <bounce/>
            <friction>
              <torsional>
                <ode/>
              </torsional>
              <ode/>
            </friction>
          </surface>
        </collision>
        <visual name='forearm_roll_link_visual'>
          <pose frame=''>0 0 0 0 -0 0</pose>
          <geometry>
            <mesh>
              <scale>1 1 1</scale>
              <uri>/home/fitter/catkin_ws/src/fetch_ros/fetch_description/meshes/forearm_roll_link.dae</uri>
            </mesh>
          </geometry>
        </visual>
        <self_collide>0</self_collide>
        <kinematic>0</kinematic>
        <gravity>1</gravity>
      </link>
      <joint name='forearm_roll_joint' type='revolute'>
        <child>forearm_roll_link</child>
        <parent>elbow_flex_link</parent>
        <axis>
          <xyz>1 0 0</xyz>
          <limit>
            <lower>-1e+16</lower>
            <upper>1e+16</upper>
          </limit>
          <dynamics>
            <damping>5</damping>
            <friction>0</friction>
            <spring_reference>0</spring_reference>
            <spring_stiffness>0</spring_stiffness>
          </dynamics>
          <use_parent_model_frame>1</use_parent_model_frame>
        </axis>
        <physics>
          <ode>
            <implicit_spring_damper>1</implicit_spring_damper>
            <cfm_damping>1</cfm_damping>
            <limit>
              <cfm>0</cfm>
              <erp>0.2</erp>
            </limit>
          </ode>
        </physics>
      </joint>
      <link name='wrist_flex_link'>
        <pose frame=''>0.82315 0 0.78601 0 -0 0</pose>
        <inertial>
          <pose frame=''>0.0882 0.0009 -0.0001 0 -0 0</pose>
          <mass>1.725</mass>
          <inertia>
            <ixx>0.0018</ixx>
            <ixy>-0.0001</ixy>
            <ixz>-0</ixz>
            <iyy>0.0042</iyy>
            <iyz>0</iyz>
            <izz>0.0042</izz>
          </inertia>
        </inertial>
        <collision name='wrist_flex_link_collision'>
          <pose frame=''>0 0 0 0 -0 0</pose>
          <geometry>
            <mesh>
              <scale>1 1 1</scale>
              <uri>/home/fitter/catkin_ws/src/fetch_ros/fetch_description/meshes/wrist_flex_link_collision.STL</uri>
            </mesh>
          </geometry>
          <max_contacts>10</max_contacts>
          <surface>
            <contact>
              <ode/>
            </contact>
            <bounce/>
            <friction>
              <torsional>
                <ode/>
              </torsional>
              <ode/>
            </friction>
          </surface>
        </collision>
        <visual name='wrist_flex_link_visual'>
          <pose frame=''>0 0 0 0 -0 0</pose>
          <geometry>
            <mesh>
              <scale>1 1 1</scale>
              <uri>/home/fitter/catkin_ws/src/fetch_ros/fetch_description/meshes/wrist_flex_link.dae</uri>
            </mesh>
          </geometry>
        </visual>
        <self_collide>0</self_collide>
        <kinematic>0</kinematic>
        <gravity>1</gravity>
      </link>
      <joint name='wrist_flex_joint' type='revolute'>
        <child>wrist_flex_link</child>
        <parent>forearm_roll_link</parent>
        <axis>
          <xyz>0 1 0</xyz>
          <limit>
            <lower>-2.16</lower>
            <upper>2.16</upper>
            <effort>25.7</effort>
            <velocity>2.268</velocity>
          </limit>
          <dynamics>
            <damping>1</damping>
            <friction>0</friction>
            <spring_reference>0</spring_reference>
            <spring_stiffness>0</spring_stiffness>
          </dynamics>
          <use_parent_model_frame>1</use_parent_model_frame>
        </axis>
      </joint>
      <link name='wrist_roll_link'>
        <pose frame=''>0.96165 0 0.78601 0 -0 0</pose>
        <inertial>
          <pose frame=''>0.070966 -5.9e-05 -0.001577 0 -0 0</pose>
          <mass>1.6529</mass>
          <inertia>
            <ixx>0.00140031</ixx>
            <ixy>4.16123e-06</ixy>
            <ixz>1.24837e-05</ixz>
            <iyy>0.00255747</iyy>
            <iyz>-9.32314e-08</iyz>
            <izz>0.00305722</izz>
          </inertia>
        </inertial>
        <collision name='wrist_roll_link_collision'>
          <pose frame=''>0 0 0 0 -0 0</pose>
          <geometry>
            <mesh>
              <scale>1 1 1</scale>
              <uri>/home/fitter/catkin_ws/src/fetch_ros/fetch_description/meshes/wrist_roll_link_collision.STL</uri>
            </mesh>
          </geometry>
          <max_contacts>10</max_contacts>
          <surface>
            <contact>
              <ode/>
            </contact>
            <bounce/>
            <friction>
              <torsional>
                <ode/>
              </torsional>
              <ode/>
            </friction>
          </surface>
        </collision>
        <collision name='wrist_roll_link_fixed_joint_lump__gripper_link_collision_1'>
          <pose frame=''>0.16645 0 0 0 -0 0</pose>
          <geometry>
            <mesh>
              <scale>1 1 1</scale>
              <uri>/home/fitter/catkin_ws/src/fetch_ros/fetch_description/meshes/gripper_link.STL</uri>
            </mesh>
          </geometry>
          <max_contacts>10</max_contacts>
          <surface>
            <contact>
              <ode/>
            </contact>
            <bounce/>
            <friction>
              <torsional>
                <ode/>
              </torsional>
              <ode/>
            </friction>
          </surface>
        </collision>
        <visual name='wrist_roll_link_visual'>
          <pose frame=''>0 0 0 0 -0 0</pose>
          <geometry>
            <mesh>
              <scale>1 1 1</scale>
              <uri>/home/fitter/catkin_ws/src/fetch_ros/fetch_description/meshes/wrist_roll_link.dae</uri>
            </mesh>
          </geometry>
        </visual>
        <visual name='wrist_roll_link_fixed_joint_lump__gripper_link_visual_1'>
          <pose frame=''>0.16645 0 0 0 -0 0</pose>
          <geometry>
            <mesh>
              <scale>1 1 1</scale>
              <uri>/home/fitter/catkin_ws/src/fetch_ros/fetch_description/meshes/gripper_link.dae</uri>
            </mesh>
          </geometry>
        </visual>
        <self_collide>0</self_collide>
        <kinematic>0</kinematic>
        <gravity>1</gravity>
      </link>
      <joint name='wrist_roll_joint' type='revolute'>
        <child>wrist_roll_link</child>
        <parent>wrist_flex_link</parent>
        <axis>
          <xyz>1 0 0</xyz>
          <limit>
            <lower>-1e+16</lower>
            <upper>1e+16</upper>
          </limit>
          <dynamics>
            <damping>5</damping>
            <friction>0</friction>
            <spring_reference>0</spring_reference>
            <spring_stiffness>0</spring_stiffness>
          </dynamics>
          <use_parent_model_frame>1</use_parent_model_frame>
        </axis>
        <physics>
          <ode>
            <implicit_spring_damper>1</implicit_spring_damper>
            <cfm_damping>1</cfm_damping>
            <limit>
              <cfm>0</cfm>
              <erp>0.2</erp>
            </limit>
          </ode>
        </physics>
      </joint>
      <link name='l_gripper_finger_link'>
        <pose frame=''>1.1281 -0.015425 0.78601 0 -0 0</pose>
        <inertial>
          <pose frame=''>-0.01 0 0 0 -0 0</pose>
          <mass>0.0798</mass>
          <inertia>
            <ixx>0.002</ixx>
            <ixy>0</ixy>
            <ixz>0</ixz>
            <iyy>0</iyy>
            <iyz>0</iyz>
            <izz>0</izz>
          </inertia>
        </inertial>
        <collision name='l_gripper_finger_link_collision'>
          <pose frame=''>0 -0.101425 0 0 -0 0</pose>
          <geometry>
            <mesh>
              <scale>1 1 1</scale>
              <uri>/home/fitter/catkin_ws/src/fetch_ros/fetch_description/meshes/l_gripper_finger_link.STL</uri>
            </mesh>
          </geometry>
          <surface>
            <contact>
              <ode>
                <kp>1e+06</kp>
                <kd>100</kd>
                <max_vel>1</max_vel>
                <min_depth>0.001</min_depth>
              </ode>
            </contact>
            <friction>
              <ode>
                <mu>30</mu>
                <mu2>30</mu2>
              </ode>
              <torsional>
                <ode/>
              </torsional>
            </friction>
            <bounce/>
          </surface>
          <max_contacts>10</max_contacts>
        </collision>
        <visual name='l_gripper_finger_link_visual'>
          <pose frame=''>0 -0.101425 0 0 -0 0</pose>
          <geometry>
            <mesh>
              <scale>1 1 1</scale>
              <uri>/home/fitter/catkin_ws/src/fetch_ros/fetch_description/meshes/l_gripper_finger_link.STL</uri>
            </mesh>
          </geometry>
          <material>
            <script>
              <name>Gazebo/Grey</name>
              <uri>file://media/materials/scripts/gazebo.material</uri>
            </script>
          </material>
        </visual>
        <gravity>1</gravity>
        <velocity_decay/>
        <self_collide>0</self_collide>
        <kinematic>0</kinematic>
      </link>
      <joint name='l_gripper_finger_joint' type='prismatic'>
        <child>l_gripper_finger_link</child>
        <parent>wrist_roll_link</parent>
        <axis>
          <xyz>0 -1 0</xyz>
          <limit>
            <lower>0</lower>
            <upper>0.05</upper>
            <effort>60</effort>
            <velocity>0.05</velocity>
          </limit>
          <dynamics>
            <damping>100</damping>
            <friction>0</friction>
            <spring_reference>0</spring_reference>
            <spring_stiffness>0</spring_stiffness>
          </dynamics>
          <use_parent_model_frame>1</use_parent_model_frame>
        </axis>
      </joint>
      <link name='r_gripper_finger_link'>
        <pose frame=''>1.1281 0.015425 0.78601 0 -0 0</pose>
        <inertial>
          <pose frame=''>-0.01 0 0 0 -0 0</pose>
          <mass>0.0798</mass>
          <inertia>
            <ixx>0.002</ixx>
            <ixy>0</ixy>
            <ixz>0</ixz>
            <iyy>0</iyy>
            <iyz>0</iyz>
            <izz>0</izz>
          </inertia>
        </inertial>
        <collision name='r_gripper_finger_link_collision'>
          <pose frame=''>0 0.101425 0 0 -0 0</pose>
          <geometry>
            <mesh>
              <scale>1 1 1</scale>
              <uri>/home/fitter/catkin_ws/src/fetch_ros/fetch_description/meshes/r_gripper_finger_link.STL</uri>
            </mesh>
          </geometry>
          <surface>
            <contact>
              <ode>
                <kp>1e+06</kp>
                <kd>100</kd>
                <max_vel>1</max_vel>
                <min_depth>0.001</min_depth>
              </ode>
            </contact>
            <friction>
              <ode>
                <mu>30</mu>
                <mu2>30</mu2>
              </ode>
              <torsional>
                <ode/>
              </torsional>
            </friction>
            <bounce/>
          </surface>
          <max_contacts>10</max_contacts>
        </collision>
        <visual name='r_gripper_finger_link_visual'>
          <pose frame=''>0 0.101425 0 0 -0 0</pose>
          <geometry>
            <mesh>
              <scale>1 1 1</scale>
              <uri>/home/fitter/catkin_ws/src/fetch_ros/fetch_description/meshes/r_gripper_finger_link.STL</uri>
            </mesh>
          </geometry>
          <material>
            <script>
              <name>Gazebo/Grey</name>
              <uri>file://media/materials/scripts/gazebo.material</uri>
            </script>
          </material>
        </visual>
        <gravity>1</gravity>
        <velocity_decay/>
        <self_collide>0</self_collide>
        <kinematic>0</kinematic>
      </link>
      <joint name='r_gripper_finger_joint' type='prismatic'>
        <child>r_gripper_finger_link</child>
        <parent>wrist_roll_link</parent>
        <axis>
          <xyz>0 1 -0</xyz>
          <limit>
            <lower>0</lower>
            <upper>0.05</upper>
            <effort>60</effort>
            <velocity>0.05</velocity>
          </limit>
          <dynamics>
            <damping>100</damping>
            <friction>0</friction>
            <spring_reference>0</spring_reference>
            <spring_stiffness>0</spring_stiffness>
          </dynamics>
          <use_parent_model_frame>1</use_parent_model_frame>
        </axis>
      </joint>
      <static>0</static>
      <plugin name='fetch_gazebo_plugin' filename='libfetch_gazebo_plugin.so'>
        <robotNamespace>/</robotNamespace>
      </plugin>
      <pose frame=''>0 0 0 0 -0 0</pose>
    </model>
    <state world_name='default'>
      <sim_time>227 633000000</sim_time>
      <real_time>43 773011760</real_time>
      <wall_time>1522328627 757293422</wall_time>
      <iterations>27878</iterations>
      <model name='demo_cube'>
        <pose frame=''>0.654266 -0.584716 0.14515 0 0 -0.010091</pose>
        <scale>1 1 4.90503</scale>
        <link name='link'>
          <pose frame=''>0.654266 -0.584716 0.14515 0 0 -0.010091</pose>
          <velocity>0 0 0 0 -0 0</velocity>
          <acceleration>8e-06 8e-06 0 -1.5e-05 1.6e-05 0.000713</acceleration>
          <wrench>2e-06 2e-06 0 0 -0 0</wrench>
        </link>
      </model>
      <model name='drill'>
        <pose frame=''>0.634961 0.059509 0.692934 0 -4.8e-05 -0.678655</pose>
        <scale>1 1 1</scale>
        <link name='link'>
          <pose frame=''>0.634961 0.059509 0.692934 0 -4.8e-05 -0.678655</pose>
          <velocity>0 0 0 0 -0 0</velocity>
          <acceleration>0 0 -9.8 -0.00016 0.000185 9e-06</acceleration>
          <wrench>0 0 -14.7247 0 -0 0</wrench>
        </link>
      </model>
      <model name='fetch'>
        <pose frame=''>0.004625 0.001772 0.000434 -0.003447 -2.2e-05 0.229799</pose>
        <scale>1 1 1</scale>
        <link name='base_link'>
          <pose frame=''>0.004625 0.001772 0.000434 -0.003447 -2.2e-05 0.229799</pose>
          <velocity>-0.001173 -0.000797 -0.001285 -0.004073 0.011522 -0.006461</velocity>
          <acceleration>0.726388 -0.057327 -1.00714 -2.87212 1.03026 2.10502</acceleration>
          <wrench>60.5932 -4.78205 -84.0127 0 -0 0</wrench>
        </link>
        <link name='bellows_link'>
          <pose frame=''>-0.080265 -0.016775 0.370906 -0.003447 -2.1e-05 0.2298</pose>
          <velocity>0.002934 0.001253 0.000375 -0.004115 0.011819 -0.006504</velocity>
          <acceleration>0.82067 -0.052311 -0.07281 -2.16118 0.77486 2.46169</acceleration>
          <wrench>0.139 -0.00886 -0.012332 0 -0 0</wrench>
        </link>
        <link name='elbow_flex_link'>
          <pose frame=''>0.044045 0.397192 0.558353 -0.003191 -1.29646 1.55294</pose>
          <velocity>-0.014077 0.004192 -0.000965 0.01093 0.069983 0.008146</velocity>
          <acceleration>-4.30706 3.38524 0.845894 2.23285 0.671548 1.87713</acceleration>
          <wrench>-9.1736 7.21022 1.80167 0 -0 0</wrench>
        </link>
        <link name='forearm_roll_link'>
          <pose frame=''>0.044999 0.450552 0.747985 -0.003425 -1.29646 1.55295</pose>
          <velocity>0.002434 0.002804 -0.001522 0.011922 -0.047709 -0.40186</velocity>
          <acceleration>23.8198 -16.6119 0.446367 1.95348 -0.085203 -0.003668</acceleration>
          <wrench>39.4527 -27.5143 0.739318 0 -0 0</wrench>
        </link>
        <link name='head_pan_link'>
          <pose frame=''>-0.029028 -0.00263 0.980859 -0.003447 1.9e-05 0.241667</pose>
          <velocity>0.010186 0.0034 -0.000876 -0.00408 0.011769 0.003641</velocity>
          <acceleration>2.69817 -0.068316 -1.05917 -2.48811 0.765068 3.09296</acceleration>
          <wrench>6.08599 -0.154094 -2.38907 0 -0 0</wrench>
        </link>
        <link name='head_tilt_link'>
          <pose frame=''>0.109313 0.031675 1.03886 -0.003447 0.004698 0.241651</pose>
          <velocity>0.010748 0.004143 -0.002646 0.006247 -0.03013 0.003795</velocity>
          <acceleration>2.31149 0.569724 -1.08071 -0.945847 -0.542145 3.11222</acceleration>
          <wrench>2.10045 0.517708 -0.982044 0 -0 0</wrench>
        </link>
        <link name='l_gripper_finger_link'>
          <pose frame=''>0.108905 0.394042 1.1596 -3.13846 -1.27503 -1.59472</pose>
          <velocity>0.172513 0.000555 -0.000745 -0.001903 0.007541 0.001196</velocity>
          <acceleration>348.024 1.22733 -1.76019 -1.89806 -0.527132 -3.14159</acceleration>
          <wrench>27.7723 0.097941 -0.140463 0 -0 0</wrench>
        </link>
        <link name='l_wheel_link'>
          <pose frame=''>-0.036843 0.184704 0.055113 -0.004006 -0.510272 0.231765</pose>
          <velocity>0.000604 -0.000184 -0.00156 0.006867 -0.003918 -0.000982</velocity>
          <acceleration>0.753278 -0.022046 -0.924567 -1.69037 0.206276 0.035287</acceleration>
          <wrench>3.27992 -0.095993 -4.02575 0 -0 0</wrench>
        </link>
        <link name='r_gripper_finger_link'>
          <pose frame=''>-0.021963 0.396779 1.15948 -3.13843 -1.27501 -1.59475</pose>
          <velocity>-0.163212 0.00636 -0.001375 0.005152 -0.012902 -0.001704</velocity>
          <acceleration>-322.995 14.021 -3.30925 0.193633 -1.03159 3.14159</acceleration>
          <wrench>-25.775 1.11888 -0.264079 0 -0 0</wrench>
        </link>
        <link name='r_wheel_link'>
          <pose frame=''>0.04852 -0.180202 0.056405 -0.004132 0.569451 0.22758</pose>
          <velocity>-0.001711 -0.000734 -0.001059 0.00953 -0.017218 -0.004711</velocity>
          <acceleration>0.55502 -0.031525 -1.21311 0.601414 -1.1302 2.4999</acceleration>
          <wrench>2.41667 -0.137267 -5.28212 0 -0 0</wrench>
        </link>
        <link name='shoulder_lift_link'>
          <pose frame=''>0.038231 0.128818 0.78605 -0.001147 0.703468 1.54913</pose>
          <velocity>0.002879 0.002269 -0.002289 0.005808 0.019323 0.042029</velocity>
          <acceleration>-8.61246 0.304527 -0.424493 0.718393 -0.719474 -0.979791</acceleration>
          <wrench>-22.9221 0.810499 -1.12979 0 -0 0</wrench>
        </link>
        <link name='shoulder_pan_link'>
          <pose frame=''>0.035832 0.011643 0.72644 -0.000877 0.003332 1.54987</pose>
          <velocity>0.007947 0.001932 -0.0018 -0.004059 0.009 0.042599</velocity>
          <acceleration>-0.458766 0.043899 -1.31338 -0.713366 -0.023652 -2.33755</acceleration>
          <wrench>-1.17385 0.112325 -3.36056 0 -0 0</wrench>
        </link>
        <link name='torso_lift_link'>
          <pose frame=''>-0.08027 -0.016752 0.37786 -0.003447 -2.2e-05 0.229799</pose>
          <velocity>0.00305 0.001282 -0.000224 -0.004063 0.01158 -0.006429</velocity>
          <acceleration>1.90739 -0.130525 -0.882177 -2.94435 0.986957 2.74708</acceleration>
          <wrench>20.884 -1.42912 -9.65896 0 -0 0</wrench>
        </link>
        <link name='upperarm_roll_link'>
          <pose frame=''>0.041848 0.295789 0.644386 -0.001137 0.703468 1.54913</pose>
          <velocity>-0.008411 0.003289 -0.001416 0.006654 0.064534 0.006169</velocity>
          <acceleration>-20.1046 1.72369 0.514179 0.051789 0.917044 3.03783</acceleration>
          <wrench>-46.8658 4.0181 1.1986 0 -0 0</wrench>
        </link>
        <link name='wrist_flex_link'>
          <pose frame=''>0.045603 0.484275 0.86783 -3.13845 -1.275 -1.59494</pose>
          <velocity>0.014554 0.00116 -0.00125 -0.013656 -0.017734 -0.390332</velocity>
          <acceleration>10.4087 7.77751 -2.35085 -0.860301 -1.15789 2.29924</acceleration>
          <wrench>17.9551 13.4162 -4.05522 0 -0 0</wrench>
        </link>
        <link name='wrist_roll_link'>
          <pose frame=''>0.044632 0.443916 1.00032 -3.13826 -1.275 -1.59491</pose>
          <velocity>0.003229 0.00294 -0.000864 -0.015101 -0.109632 -0.010815</velocity>
          <acceleration>-6.28549 8.83782 -2.04937 2.74068 -0.22877 2.80328</acceleration>
          <wrench>-10.3893 14.608 -3.3874 0 -0 0</wrench>
        </link>
      </model>
      <model name='ground_plane'>
        <pose frame=''>0 0 0 0 -0 0</pose>
        <scale>1 1 1</scale>
        <link name='link'>
          <pose frame=''>0 0 0 0 -0 0</pose>
          <velocity>0 0 0 0 -0 0</velocity>
          <acceleration>0 0 0 0 -0 0</acceleration>
          <wrench>0 0 0 0 -0 0</wrench>
        </link>
      </model>
      <model name='table1'>
        <pose frame=''>1 0 -0.08 0 -0 0</pose>
        <scale>1 1 1</scale>
        <link name='link'>
          <pose frame=''>1 0 -0.08 0 -0 0</pose>
          <velocity>0 0 0 0 -0 0</velocity>
          <acceleration>0 0 0 0 -0 0</acceleration>
          <wrench>0 0 0 0 -0 0</wrench>
        </link>
      </model>
      <model name='table2'>
        <pose frame=''>-3 5 0 0 -0 1.57</pose>
        <scale>1 1 1</scale>
        <link name='link'>
          <pose frame=''>-3 5 0 0 -0 1.57</pose>
          <velocity>0 0 0 0 -0 0</velocity>
          <acceleration>0 0 0 0 -0 0</acceleration>
          <wrench>0 0 0 0 -0 0</wrench>
        </link>
      </model>
      <model name='test_zone'>
        <pose frame=''>-0.338278 -0.059964 0 0 -0 0</pose>
        <scale>1 1 1</scale>
        <link name='link'>
          <pose frame=''>-0.338278 -0.059964 0 0 -0 0</pose>
          <velocity>0 0 0 0 -0 0</velocity>
          <acceleration>0 0 0 0 -0 0</acceleration>
          <wrench>0 0 0 0 -0 0</wrench>
        </link>
      </model>
      <light name='sun'>
        <pose frame=''>0 0 10 0 -0 0</pose>
      </light>
    </state>
    <gui fullscreen='0'>
      <camera name='user_camera'>
        <pose frame=''>2.7604 2.54492 2.04886 0 0.431643 -2.21899</pose>
        <view_controller>orbit</view_controller>
        <projection_type>perspective</projection_type>
      </camera>
    </gui>
    <model name='drill'>
      <link name='link'>
        <inertial>
          <pose frame=''>-0.00637 -0.008 0.13254 0 -0 0</pose>
          <inertia>
            <ixx>0.0133113</ixx>
            <ixy>-0.00030365</ixy>
            <ixz>-0.00034148</ixz>
            <iyy>0.0115766</iyy>
            <iyz>0.00088073</iyz>
            <izz>0.00378028</izz>
          </inertia>
          <mass>1.50252</mass>
        </inertial>
        <collision name='collision'>
          <pose frame=''>0 0 -0.09 0 -0 0</pose>
          <geometry>
            <mesh>
              <uri>model://cordless_drill/meshes/cordless_drill.stl</uri>
              <scale>1 1 1</scale>
            </mesh>
          </geometry>
          <max_contacts>10</max_contacts>
          <surface>
            <contact>
              <ode/>
            </contact>
            <bounce/>
            <friction>
              <torsional>
                <ode/>
              </torsional>
              <ode/>
            </friction>
          </surface>
        </collision>
        <visual name='visual'>
          <pose frame=''>0 0 -0.09 0 -0 0</pose>
          <geometry>
            <mesh>
              <uri>model://cordless_drill/meshes/cordless_drill.dae</uri>
              <scale>1 1 1</scale>
            </mesh>
          </geometry>
        </visual>
        <self_collide>0</self_collide>
        <kinematic>0</kinematic>
        <gravity>1</gravity>
      </link>
      <pose frame=''>0.60847 0.027116 0 0 -0 0</pose>
    </model>
  </world>
</sdf>
