<sdf version='1.6'>
  <world name='default'>
    <physics name='default_physics' default='0' type='ode'>
      <ode>
        <solver>
          <type>quick</type>
          <iters>20</iters>
          <sor>1</sor>
          <use_dynamic_moi_rescaling>0</use_dynamic_moi_rescaling>
        </solver>
        <constraints>
          <cfm>0</cfm>
          <erp>0.2</erp>
          <contact_max_correcting_vel>100</contact_max_correcting_vel>
          <contact_surface_layer>0</contact_surface_layer>
        </constraints>
      </ode>
      <real_time_update_rate>1000</real_time_update_rate>
      <max_step_size>0.001</max_step_size>
      <real_time_factor>1</real_time_factor>
    </physics>
    <light name='light1' type='directional'>
      <cast_shadows>1</cast_shadows>
      <pose frame=''>-2 0 4 0 -0 0</pose>
      <diffuse>1 1 1 1</diffuse>
      <specular>0.1 0.1 0.1 1</specular>
      <attenuation>
        <range>20</range>
        <constant>0.9</constant>
        <linear>0.01</linear>
        <quadratic>0.001</quadratic>
      </attenuation>
      <direction>0.2 0 -1</direction>
    </light>
    <model name='ground_plane'>
      <static>1</static>
      <link name='link'>
        <collision name='collision'>
          <geometry>
            <plane>
              <normal>0 0 1</normal>
              <size>100 100</size>
            </plane>
          </geometry>
          <surface>
            <friction>
              <ode>
                <mu>100</mu>
                <mu2>50</mu2>
              </ode>
              <torsional>
                <ode/>
              </torsional>
            </friction>
            <contact>
              <ode/>
            </contact>
            <bounce/>
          </surface>
          <max_contacts>10</max_contacts>
        </collision>
        <visual name='visual'>
          <cast_shadows>0</cast_shadows>
          <geometry>
            <plane>
              <normal>0 0 1</normal>
              <size>100 100</size>
            </plane>
          </geometry>
          <material>
            <script>
              <uri>file://media/materials/scripts/gazebo.material</uri>
              <name>Gazebo/Grey</name>
            </script>
          </material>
        </visual>
        <self_collide>0</self_collide>
        <kinematic>0</kinematic>
        <gravity>1</gravity>
      </link>
    </model>
    <model name='table1'>
      <static>1</static>
      <link name='link'>
        <collision name='surface'>
          <pose frame=''>0 0 0.8 0 -0 0</pose>
          <geometry>
            <box>
              <size>1 0.8 0.03</size>
            </box>
          </geometry>
          <surface>
            <bounce/>
            <friction>
              <ode/>
              <torsional>
                <ode/>
              </torsional>
            </friction>
            <contact>
              <ode/>
            </contact>
          </surface>
          <max_contacts>10</max_contacts>
        </collision>
        <visual name='visual1'>
          <pose frame=''>0 0 0.8 0 -0 0</pose>
          <geometry>
            <box>
              <size>1 0.8 0.03</size>
            </box>
          </geometry>
          <material>
            <script>
              <uri>file://media/materials/scripts/gazebo.material</uri>
              <name>Gazebo/Wood</name>
            </script>
          </material>
        </visual>
        <collision name='front_left_leg'>
          <pose frame=''>0.48 0.38 0.4 0 -0 0</pose>
          <geometry>
            <cylinder>
              <radius>0.02</radius>
              <length>0.8</length>
            </cylinder>
          </geometry>
          <surface>
            <bounce/>
            <friction>
              <ode/>
              <torsional>
                <ode/>
              </torsional>
            </friction>
            <contact>
              <ode/>
            </contact>
          </surface>
          <max_contacts>10</max_contacts>
        </collision>
        <visual name='front_left_leg'>
          <pose frame=''>0.48 0.38 0.4 0 -0 0</pose>
          <geometry>
            <cylinder>
              <radius>0.02</radius>
              <length>0.8</length>
            </cylinder>
          </geometry>
          <material>
            <script>
              <uri>file://media/materials/scripts/gazebo.material</uri>
              <name>Gazebo/Grey</name>
            </script>
          </material>
        </visual>
        <collision name='front_right_leg'>
          <pose frame=''>0.48 -0.38 0.4 0 -0 0</pose>
          <geometry>
            <cylinder>
              <radius>0.02</radius>
              <length>0.8</length>
            </cylinder>
          </geometry>
          <surface>
            <bounce/>
            <friction>
              <ode/>
              <torsional>
                <ode/>
              </torsional>
            </friction>
            <contact>
              <ode/>
            </contact>
          </surface>
          <max_contacts>10</max_contacts>
        </collision>
        <visual name='front_right_leg'>
          <pose frame=''>0.48 -0.38 0.4 0 -0 0</pose>
          <geometry>
            <cylinder>
              <radius>0.02</radius>
              <length>0.8</length>
            </cylinder>
          </geometry>
          <material>
            <script>
              <uri>file://media/materials/scripts/gazebo.material</uri>
              <name>Gazebo/Grey</name>
            </script>
          </material>
        </visual>
        <collision name='back_right_leg'>
          <pose frame=''>-0.48 -0.38 0.4 0 -0 0</pose>
          <geometry>
            <cylinder>
              <radius>0.02</radius>
              <length>0.8</length>
            </cylinder>
          </geometry>
          <surface>
            <bounce/>
            <friction>
              <ode/>
              <torsional>
                <ode/>
              </torsional>
            </friction>
            <contact>
              <ode/>
            </contact>
          </surface>
          <max_contacts>10</max_contacts>
        </collision>
        <visual name='back_right_leg'>
          <pose frame=''>-0.48 -0.38 0.4 0 -0 0</pose>
          <geometry>
            <cylinder>
              <radius>0.02</radius>
              <length>0.8</length>
            </cylinder>
          </geometry>
          <material>
            <script>
              <uri>file://media/materials/scripts/gazebo.material</uri>
              <name>Gazebo/Grey</name>
            </script>
          </material>
        </visual>
        <collision name='back_left_leg'>
          <pose frame=''>-0.48 0.38 0.4 0 -0 0</pose>
          <geometry>
            <cylinder>
              <radius>0.02</radius>
              <length>0.8</length>
            </cylinder>
          </geometry>
          <surface>
            <bounce/>
            <friction>
              <ode/>
              <torsional>
                <ode/>
              </torsional>
            </friction>
            <contact>
              <ode/>
            </contact>
          </surface>
          <max_contacts>10</max_contacts>
        </collision>
        <visual name='back_left_leg'>
          <pose frame=''>-0.48 0.38 0.4 0 -0 0</pose>
          <geometry>
            <cylinder>
              <radius>0.02</radius>
              <length>0.8</length>
            </cylinder>
          </geometry>
          <material>
            <script>
              <uri>file://media/materials/scripts/gazebo.material</uri>
              <name>Gazebo/Grey</name>
            </script>
          </material>
        </visual>
        <velocity_decay>
          <linear>0</linear>
          <angular>0</angular>
        </velocity_decay>
        <self_collide>0</self_collide>
        <kinematic>0</kinematic>
        <gravity>1</gravity>
      </link>
      <pose frame=''>0.88 0 0 0 -0 0</pose>
    </model>
    <model name='aruco_cube'>
      <static>0</static>
      <link name='link'>
        <inertial>
          <mass>0.05</mass>
          <inertia>
            <ixx>5.2083e-05</ixx>
            <ixy>0</ixy>
            <ixz>0</ixz>
            <iyy>5.2083e-05</iyy>
            <iyz>0</iyz>
            <izz>2.0833e-05</izz>
          </inertia>
        </inertial>
        <collision name='colision'>
          <pose frame=''>0 0 0 0 -0 0</pose>
          <geometry>
            <box>
              <size>0.05 0.05 0.1</size>
            </box>
          </geometry>
          <surface>
            <friction>
              <ode>
                <mu>30</mu>
                <mu2>30</mu2>
                <fdir1>0 0 0</fdir1>
              </ode>
              <torsional>
                <ode/>
              </torsional>
            </friction>
            <contact>
              <ode>
                <kp>1e+06</kp>
                <kd>100</kd>
                <min_depth>0.0025</min_depth>
                <max_vel>1</max_vel>
              </ode>
            </contact>
            <bounce/>
          </surface>
          <max_contacts>10</max_contacts>
        </collision>
        <visual name='visual1'>
          <pose frame=''>0 0 0 0 -0 0</pose>
          <geometry>
            <mesh>
              <uri>model://aruco_cube/meshes/aruco_cube_5cm.dae</uri>
              <scale>1 1 1</scale>
            </mesh>
          </geometry>
        </visual>
        <velocity_decay>
          <linear>0</linear>
          <angular>0</angular>
        </velocity_decay>
        <self_collide>0</self_collide>
        <kinematic>0</kinematic>
        <gravity>1</gravity>
      </link>
      <pose frame=''>0.53 -0.05 1.2 0 -0 0</pose>
    </model>
    <gui fullscreen='0'>
      <camera name='user_camera'>
        <pose frame=''>0.462271 3.18226 3.00375 0 0.68764 -1.527</pose>
        <view_controller>orbit</view_controller>
        <projection_type>perspective</projection_type>
      </camera>
    </gui>
    <gravity>0 0 -9.81</gravity>
    <magnetic_field>6e-06 2.3e-05 -4.2e-05</magnetic_field>
    <atmosphere type='adiabatic'/>
    <scene>
      <ambient>0.4 0.4 0.4 1</ambient>
      <background>0.7 0.7 0.7 1</background>
      <shadows>1</shadows>
    </scene>
    <spherical_coordinates>
      <surface_model>EARTH_WGS84</surface_model>
      <latitude_deg>0</latitude_deg>
      <longitude_deg>0</longitude_deg>
      <elevation>0</elevation>
      <heading_deg>0</heading_deg>
    </spherical_coordinates>
    <model name='tiago_steel'>
      <link name='base_footprint'>
        <pose frame=''>0 0 0 0 -0 0</pose>
        <inertial>
          <pose frame=''>-0.009836 -0.001501 0.21148 0 -0 0</pose>
          <mass>43.4016</mass>
          <inertia>
            <ixx>2.04327</ixx>
            <ixy>0.000744547</ixy>
            <ixz>0.109545</ixz>
            <iyy>2.13173</iyy>
            <iyz>0.0140814</iyz>
            <izz>0.688729</izz>
          </inertia>
        </inertial>
        <collision name='base_footprint_fixed_joint_lump__base_link_collision'>
          <pose frame=''>0 0 0.0985 0 -0 0</pose>
          <geometry>
            <mesh>
              <scale>1 1 1</scale>
              <uri>/home/fitter/tiago_public_ws/src/pmb2_robot/pmb2_description/meshes/base/base_collision.dae</uri>
            </mesh>
          </geometry>
          <surface>
            <contact>
              <ode/>
            </contact>
            <friction>
              <ode/>
              <torsional>
                <ode/>
              </torsional>
            </friction>
            <bounce/>
          </surface>
          <max_contacts>10</max_contacts>
        </collision>
        <collision name='base_footprint_fixed_joint_lump__base_antenna_left_link_collision_1'>
          <pose frame=''>-0.201 0.1062 0.3785 0 -0 0</pose>
          <geometry>
            <cylinder>
              <length>0.17</length>
              <radius>0.005</radius>
            </cylinder>
          </geometry>
          <surface>
            <contact>
              <ode/>
            </contact>
            <friction>
              <ode/>
              <torsional>
                <ode/>
              </torsional>
            </friction>
            <bounce/>
          </surface>
          <max_contacts>10</max_contacts>
        </collision>
        <collision name='base_footprint_fixed_joint_lump__base_antenna_right_link_collision_2'>
          <pose frame=''>-0.201 -0.1062 0.3785 0 -0 0</pose>
          <geometry>
            <cylinder>
              <length>0.17</length>
              <radius>0.005</radius>
            </cylinder>
          </geometry>
          <surface>
            <contact>
              <ode/>
            </contact>
            <friction>
              <ode/>
              <torsional>
                <ode/>
              </torsional>
            </friction>
            <bounce/>
          </surface>
          <max_contacts>10</max_contacts>
        </collision>
        <collision name='base_footprint_fixed_joint_lump__torso_fixed_column_link_collision_3'>
          <pose frame=''>-0.062 0 0.5685 0 -0 0</pose>
          <geometry>
            <box>
              <size>0.23 0.23 0.55</size>
            </box>
          </geometry>
          <surface>
            <contact>
              <ode/>
            </contact>
            <friction>
              <ode/>
              <torsional>
                <ode/>
              </torsional>
            </friction>
            <bounce/>
          </surface>
          <max_contacts>10</max_contacts>
        </collision>
        <collision name='base_footprint_fixed_joint_lump__torso_fixed_link_collision_4'>
          <pose frame=''>0.023 0 0.3115 0 -0 0</pose>
          <geometry>
            <box>
              <size>0.4 0.25 0.04</size>
            </box>
          </geometry>
          <max_contacts>10</max_contacts>
          <surface>
            <contact>
              <ode/>
            </contact>
            <bounce/>
            <friction>
              <torsional>
                <ode/>
              </torsional>
              <ode/>
            </friction>
          </surface>
        </collision>
        <collision name='base_footprint_fixed_joint_lump__torso_fixed_link_collision_5'>
          <pose frame=''>-0.062 0 0.3415 0 -0 0</pose>
          <geometry>
            <box>
              <size>0.25 0.25 0.1</size>
            </box>
          </geometry>
          <max_contacts>10</max_contacts>
          <surface>
            <contact>
              <ode/>
            </contact>
            <bounce/>
            <friction>
              <torsional>
                <ode/>
              </torsional>
              <ode/>
            </friction>
          </surface>
        </collision>
        <visual name='base_footprint_fixed_joint_lump__base_link_visual'>
          <pose frame=''>0 0 0.0985 0 -0 0</pose>
          <geometry>
            <mesh>
              <scale>1 1 1</scale>
              <uri>/home/fitter/tiago_public_ws/src/pmb2_robot/pmb2_description/meshes/base/base.stl</uri>
            </mesh>
          </geometry>
          <material>
            <script>
              <name>Gazebo/White</name>
              <uri>file://media/materials/scripts/gazebo.material</uri>
            </script>
          </material>
        </visual>
        <visual name='base_footprint_fixed_joint_lump__base_antenna_left_link_visual_1'>
          <pose frame=''>-0.201 0.1062 0.2935 0 -0 0</pose>
          <geometry>
            <mesh>
              <scale>1 1 1</scale>
              <uri>/home/fitter/tiago_public_ws/src/pmb2_robot/pmb2_description/meshes/objects/antenna.stl</uri>
            </mesh>
          </geometry>
          <material>
            <script>
              <name>Gazebo/Black</name>
              <uri>file://media/materials/scripts/gazebo.material</uri>
            </script>
          </material>
        </visual>
        <visual name='base_footprint_fixed_joint_lump__base_antenna_right_link_visual_2'>
          <pose frame=''>-0.201 -0.1062 0.2935 0 -0 0</pose>
          <geometry>
            <mesh>
              <scale>1 1 1</scale>
              <uri>/home/fitter/tiago_public_ws/src/pmb2_robot/pmb2_description/meshes/objects/antenna.stl</uri>
            </mesh>
          </geometry>
          <material>
            <script>
              <name>Gazebo/Black</name>
              <uri>file://media/materials/scripts/gazebo.material</uri>
            </script>
          </material>
        </visual>
        <visual name='base_footprint_fixed_joint_lump__base_laser_link_visual_3'>
          <pose frame=''>0.202 0 0.0945 0 -0 0</pose>
          <geometry>
            <mesh>
              <scale>1 1 1</scale>
              <uri>/home/fitter/tiago_public_ws/src/pmb2_robot/pmb2_description/meshes/sensors/sick_tim551.stl</uri>
            </mesh>
          </geometry>
          <material>
            <script>
              <name>Gazebo/DarkGrey</name>
              <uri>file://media/materials/scripts/gazebo.material</uri>
            </script>
          </material>
        </visual>
        <visual name='base_footprint_fixed_joint_lump__base_sonar_01_link_visual_4'>
          <pose frame=''>-0.183 -0.183 0.2715 0 -0 -2.35619</pose>
          <geometry>
            <mesh>
              <scale>1 1 1</scale>
              <uri>/home/fitter/tiago_public_ws/src/pmb2_robot/pmb2_description/meshes/sensors/srf05.stl</uri>
            </mesh>
          </geometry>
          <material>
            <script>
              <name>Gazebo/DarkGrey</name>
              <uri>file://media/materials/scripts/gazebo.material</uri>
            </script>
          </material>
        </visual>
        <visual name='base_footprint_fixed_joint_lump__base_sonar_02_link_visual_5'>
          <pose frame=''>-0.259 0 0.2715 0 -0 -3.14159</pose>
          <geometry>
            <mesh>
              <scale>1 1 1</scale>
              <uri>/home/fitter/tiago_public_ws/src/pmb2_robot/pmb2_description/meshes/sensors/srf05.stl</uri>
            </mesh>
          </geometry>
          <material>
            <script>
              <name>Gazebo/DarkGrey</name>
              <uri>file://media/materials/scripts/gazebo.material</uri>
            </script>
          </material>
        </visual>
        <visual name='base_footprint_fixed_joint_lump__base_sonar_03_link_visual_6'>
          <pose frame=''>-0.183 0.183 0.2715 0 -0 2.35619</pose>
          <geometry>
            <mesh>
              <scale>1 1 1</scale>
              <uri>/home/fitter/tiago_public_ws/src/pmb2_robot/pmb2_description/meshes/sensors/srf05.stl</uri>
            </mesh>
          </geometry>
          <material>
            <script>
              <name>Gazebo/DarkGrey</name>
              <uri>file://media/materials/scripts/gazebo.material</uri>
            </script>
          </material>
        </visual>
        <visual name='base_footprint_fixed_joint_lump__caster_back_left_1_link_visual_7'>
          <pose frame=''>-0.1735 0.102 0.065 0 -0 0</pose>
          <geometry>
            <mesh>
              <scale>1 1 1</scale>
              <uri>/home/fitter/tiago_public_ws/src/pmb2_robot/pmb2_description/meshes/wheels/caster_1.stl</uri>
            </mesh>
          </geometry>
        </visual>
        <visual name='base_footprint_fixed_joint_lump__caster_back_left_2_link_visual_8'>
          <pose frame=''>-0.1895 0.102 0.025 -1.5708 0 0</pose>
          <geometry>
            <mesh>
              <scale>1 1 1</scale>
              <uri>/home/fitter/tiago_public_ws/src/pmb2_robot/pmb2_description/meshes/wheels/caster_2.stl</uri>
            </mesh>
          </geometry>
        </visual>
        <visual name='base_footprint_fixed_joint_lump__caster_back_right_1_link_visual_9'>
          <pose frame=''>-0.1735 -0.102 0.065 0 -0 0</pose>
          <geometry>
            <mesh>
              <scale>1 1 1</scale>
              <uri>/home/fitter/tiago_public_ws/src/pmb2_robot/pmb2_description/meshes/wheels/caster_1.stl</uri>
            </mesh>
          </geometry>
        </visual>
        <visual name='base_footprint_fixed_joint_lump__caster_back_right_2_link_visual_10'>
          <pose frame=''>-0.1895 -0.102 0.025 -1.5708 0 0</pose>
          <geometry>
            <mesh>
              <scale>1 1 1</scale>
              <uri>/home/fitter/tiago_public_ws/src/pmb2_robot/pmb2_description/meshes/wheels/caster_2.stl</uri>
            </mesh>
          </geometry>
        </visual>
        <visual name='base_footprint_fixed_joint_lump__caster_front_left_1_link_visual_11'>
          <pose frame=''>0.1695 0.102 0.065 0 -0 0</pose>
          <geometry>
            <mesh>
              <scale>1 1 1</scale>
              <uri>/home/fitter/tiago_public_ws/src/pmb2_robot/pmb2_description/meshes/wheels/caster_1.stl</uri>
            </mesh>
          </geometry>
        </visual>
        <visual name='base_footprint_fixed_joint_lump__caster_front_left_2_link_visual_12'>
          <pose frame=''>0.1535 0.102 0.025 -1.5708 0 0</pose>
          <geometry>
            <mesh>
              <scale>1 1 1</scale>
              <uri>/home/fitter/tiago_public_ws/src/pmb2_robot/pmb2_description/meshes/wheels/caster_2.stl</uri>
            </mesh>
          </geometry>
        </visual>
        <visual name='base_footprint_fixed_joint_lump__caster_front_right_1_link_visual_13'>
          <pose frame=''>0.1695 -0.102 0.065 0 -0 0</pose>
          <geometry>
            <mesh>
              <scale>1 1 1</scale>
              <uri>/home/fitter/tiago_public_ws/src/pmb2_robot/pmb2_description/meshes/wheels/caster_1.stl</uri>
            </mesh>
          </geometry>
        </visual>
        <visual name='base_footprint_fixed_joint_lump__caster_front_right_2_link_visual_14'>
          <pose frame=''>0.1535 -0.102 0.025 -1.5708 0 0</pose>
          <geometry>
            <mesh>
              <scale>1 1 1</scale>
              <uri>/home/fitter/tiago_public_ws/src/pmb2_robot/pmb2_description/meshes/wheels/caster_2.stl</uri>
            </mesh>
          </geometry>
        </visual>
        <visual name='base_footprint_fixed_joint_lump__torso_fixed_column_link_visual_15'>
          <pose frame=''>-0.062 0 0.5685 0 -0 0</pose>
          <geometry>
            <box>
              <size>0.18 0.2 0.55</size>
            </box>
          </geometry>
          <material>
            <script>
              <name>Gazebo/DarkGrey</name>
              <uri>file://media/materials/scripts/gazebo.material</uri>
            </script>
          </material>
        </visual>
        <visual name='base_footprint_fixed_joint_lump__torso_fixed_link_visual_16'>
          <pose frame=''>-0.062 0 0.2915 0 -0 0</pose>
          <geometry>
            <mesh>
              <scale>1 1 1</scale>
              <uri>/home/fitter/tiago_public_ws/src/tiago_robot/tiago_description/meshes/torso/torso_fix.stl</uri>
            </mesh>
          </geometry>
        </visual>
        <visual name='base_footprint_fixed_joint_lump__base_cover_link_visual_17'>
          <pose frame=''>0 0 0.13 0 -0 0</pose>
          <geometry>
            <mesh>
              <scale>1 1 1</scale>
              <uri>/home/fitter/tiago_public_ws/src/pmb2_robot/pmb2_description/meshes/base/base_ring.stl</uri>
            </mesh>
          </geometry>
          <material>
            <script>
              <name>Gazebo/Orange</name>
              <uri>file://media/materials/scripts/gazebo.material</uri>
            </script>
          </material>
        </visual>
        <velocity_decay/>
        <velocity_decay/>
        <velocity_decay/>
        <velocity_decay/>
        <velocity_decay/>
        <sensor name='imu_sensor' type='imu'>
          <always_on>1</always_on>
          <update_rate>1000</update_rate>
          <imu>
            <angular_velocity>
              <x>
                <noise type='gaussian'>
                  <mean>0</mean>
                  <stddev>0.0002</stddev>
                  <bias_mean>7.5e-06</bias_mean>
                  <bias_stddev>8e-07</bias_stddev>
                </noise>
              </x>
              <y>
                <noise type='gaussian'>
                  <mean>0</mean>
                  <stddev>0.0002</stddev>
                  <bias_mean>7.5e-06</bias_mean>
                  <bias_stddev>8e-07</bias_stddev>
                </noise>
              </y>
              <z>
                <noise type='gaussian'>
                  <mean>0</mean>
                  <stddev>0.0002</stddev>
                  <bias_mean>7.5e-06</bias_mean>
                  <bias_stddev>8e-07</bias_stddev>
                </noise>
              </z>
            </angular_velocity>
            <linear_acceleration>
              <x>
                <noise type='gaussian'>
                  <mean>0</mean>
                  <stddev>0.017</stddev>
                  <bias_mean>0.1</bias_mean>
                  <bias_stddev>0.001</bias_stddev>
                </noise>
              </x>
              <y>
                <noise type='gaussian'>
                  <mean>0</mean>
                  <stddev>0.017</stddev>
                  <bias_mean>0.1</bias_mean>
                  <bias_stddev>0.001</bias_stddev>
                </noise>
              </y>
              <z>
                <noise type='gaussian'>
                  <mean>0</mean>
                  <stddev>0.017</stddev>
                  <bias_mean>0.1</bias_mean>
                  <bias_stddev>0.001</bias_stddev>
                </noise>
              </z>
            </linear_acceleration>
          </imu>
          <pose frame=''>0.10171 0 0.21132 0 0 -1.5708</pose>
        </sensor>
        <velocity_decay/>
        <sensor name='base_imu_sensor' type='imu'>
          <always_on>1</always_on>
          <update_rate>100</update_rate>
          <imu>
            <angular_velocity>
              <x>
                <noise type='gaussian'>
                  <mean>0</mean>
                  <stddev>0.0002</stddev>
                  <bias_mean>7.5e-06</bias_mean>
                  <bias_stddev>8e-07</bias_stddev>
                </noise>
              </x>
              <y>
                <noise type='gaussian'>
                  <mean>0</mean>
                  <stddev>0.0002</stddev>
                  <bias_mean>7.5e-06</bias_mean>
                  <bias_stddev>8e-07</bias_stddev>
                </noise>
              </y>
              <z>
                <noise type='gaussian'>
                  <mean>0</mean>
                  <stddev>0.0002</stddev>
                  <bias_mean>7.5e-06</bias_mean>
                  <bias_stddev>8e-07</bias_stddev>
                </noise>
              </z>
            </angular_velocity>
            <linear_acceleration>
              <x>
                <noise type='gaussian'>
                  <mean>0</mean>
                  <stddev>0.017</stddev>
                  <bias_mean>0.1</bias_mean>
                  <bias_stddev>0.001</bias_stddev>
                </noise>
              </x>
              <y>
                <noise type='gaussian'>
                  <mean>0</mean>
                  <stddev>0.017</stddev>
                  <bias_mean>0.1</bias_mean>
                  <bias_stddev>0.001</bias_stddev>
                </noise>
              </y>
              <z>
                <noise type='gaussian'>
                  <mean>0</mean>
                  <stddev>0.017</stddev>
                  <bias_mean>0.1</bias_mean>
                  <bias_stddev>0.001</bias_stddev>
                </noise>
              </z>
            </linear_acceleration>
          </imu>
          <pose frame=''>0.10171 0 0.21132 0 0 -1.5708</pose>
        </sensor>
        <velocity_decay/>
        <sensor name='base_laser' type='ray'>
          <update_rate>10</update_rate>
          <visualize>1</visualize>
          <ray>
            <scan>
              <horizontal>
                <samples>666</samples>
                <resolution>1</resolution>
                <min_angle>-1.91986</min_angle>
                <max_angle>1.91986</max_angle>
              </horizontal>
              <vertical>
                <samples>1</samples>
                <min_angle>0</min_angle>
                <max_angle>0</max_angle>
              </vertical>
            </scan>
            <range>
              <min>0.05</min>
              <max>10</max>
              <resolution>0.001</resolution>
            </range>
          </ray>
          <plugin name='gazebo_ros_sick_laser' filename='libgazebo_ros_laser.so'>
            <gaussianNoise>0.06</gaussianNoise>
            <alwaysOn>true</alwaysOn>
            <updateRate>10</updateRate>
            <topicName>scan</topicName>
            <frameName>base_laser_link</frameName>
            <robotNamespace>/</robotNamespace>
          </plugin>
          <pose frame=''>0.202 0 0.0945 0 -0 0</pose>
        </sensor>
        <velocity_decay/>
        <sensor name='base_sonar_01' type='ray'>
          <update_rate>5</update_rate>
          <visualize>0</visualize>
          <ray>
            <scan>
              <horizontal>
                <samples>5</samples>
                <resolution>1</resolution>
                <min_angle>-0.25</min_angle>
                <max_angle>0.25</max_angle>
              </horizontal>
              <vertical>
                <samples>5</samples>
                <resolution>1</resolution>
                <min_angle>-0.25</min_angle>
                <max_angle>0.25</max_angle>
              </vertical>
            </scan>
            <range>
              <min>0.02</min>
              <max>2</max>
              <resolution>0.01</resolution>
            </range>
          </ray>
          <plugin name='gazebo_ros_range' filename='libgazebo_ros_range.so'>
            <gaussianNoise>0.005</gaussianNoise>
            <alwaysOn>true</alwaysOn>
            <updateRate>5</updateRate>
            <topicName>sonar_base</topicName>
            <frameName>base_sonar_01_link</frameName>
            <minRange>0.02</minRange>
            <maxRange>2.0</maxRange>
            <fov>0.5</fov>
            <radiation>ultrasound</radiation>
            <robotNamespace>/</robotNamespace>
          </plugin>
          <pose frame=''>-0.183 -0.183 0.2715 0 -0 -2.35619</pose>
        </sensor>
        <velocity_decay/>
        <sensor name='base_sonar_02' type='ray'>
          <update_rate>5</update_rate>
          <visualize>0</visualize>
          <ray>
            <scan>
              <horizontal>
                <samples>5</samples>
                <resolution>1</resolution>
                <min_angle>-0.25</min_angle>
                <max_angle>0.25</max_angle>
              </horizontal>
              <vertical>
                <samples>5</samples>
                <resolution>1</resolution>
                <min_angle>-0.25</min_angle>
                <max_angle>0.25</max_angle>
              </vertical>
            </scan>
            <range>
              <min>0.02</min>
              <max>2</max>
              <resolution>0.01</resolution>
            </range>
          </ray>
          <plugin name='gazebo_ros_range' filename='libgazebo_ros_range.so'>
            <gaussianNoise>0.005</gaussianNoise>
            <alwaysOn>true</alwaysOn>
            <updateRate>5</updateRate>
            <topicName>sonar_base</topicName>
            <frameName>base_sonar_02_link</frameName>
            <minRange>0.02</minRange>
            <maxRange>2.0</maxRange>
            <fov>0.5</fov>
            <radiation>ultrasound</radiation>
            <robotNamespace>/</robotNamespace>
          </plugin>
          <pose frame=''>-0.259 0 0.2715 0 -0 -3.14159</pose>
        </sensor>
        <velocity_decay/>
        <sensor name='base_sonar_03' type='ray'>
          <update_rate>5</update_rate>
          <visualize>0</visualize>
          <ray>
            <scan>
              <horizontal>
                <samples>5</samples>
                <resolution>1</resolution>
                <min_angle>-0.25</min_angle>
                <max_angle>0.25</max_angle>
              </horizontal>
              <vertical>
                <samples>5</samples>
                <resolution>1</resolution>
                <min_angle>-0.25</min_angle>
                <max_angle>0.25</max_angle>
              </vertical>
            </scan>
            <range>
              <min>0.02</min>
              <max>2</max>
              <resolution>0.01</resolution>
            </range>
          </ray>
          <plugin name='gazebo_ros_range' filename='libgazebo_ros_range.so'>
            <gaussianNoise>0.005</gaussianNoise>
            <alwaysOn>true</alwaysOn>
            <updateRate>5</updateRate>
            <topicName>sonar_base</topicName>
            <frameName>base_sonar_03_link</frameName>
            <minRange>0.02</minRange>
            <maxRange>2.0</maxRange>
            <fov>0.5</fov>
            <radiation>ultrasound</radiation>
            <robotNamespace>/</robotNamespace>
          </plugin>
          <pose frame=''>-0.183 0.183 0.2715 0 -0 2.35619</pose>
        </sensor>
        <velocity_decay/>
        <gravity>1</gravity>
        <velocity_decay/>
        <self_collide>0</self_collide>
        <kinematic>0</kinematic>
      </link>
      <link name='torso_lift_link'>
        <pose frame=''>-0.062 0 0.8885 0 -0 0</pose>
        <inertial>
          <pose frame=''>0.04361 -0.00116 -0.17334 0 -0 0</pose>
          <mass>6.93198</mass>
          <inertia>
            <ixx>0.24487</ixx>
            <ixy>-0.001456</ixy>
            <ixz>-0.009742</ixz>
            <iyy>0.249269</iyy>
            <iyz>0.008281</iyz>
            <izz>0.090395</izz>
          </inertia>
        </inertial>
        <collision name='torso_lift_link_collision'>
          <pose frame=''>0 0 0 0 -0 0</pose>
          <geometry>
            <mesh>
              <scale>1 1 1</scale>
              <uri>/home/fitter/tiago_public_ws/src/tiago_robot/tiago_description/meshes/torso/torso_lift_collision.dae</uri>
            </mesh>
          </geometry>
          <max_contacts>10</max_contacts>
          <surface>
            <contact>
              <ode/>
            </contact>
            <bounce/>
            <friction>
              <torsional>
                <ode/>
              </torsional>
              <ode/>
            </friction>
          </surface>
        </collision>
        <visual name='torso_lift_link_visual'>
          <pose frame=''>0 0 0 0 -0 0</pose>
          <geometry>
            <mesh>
              <scale>1 1 1</scale>
              <uri>/home/fitter/tiago_public_ws/src/tiago_robot/tiago_description/meshes/torso/torso_lift_with_arm.stl</uri>
            </mesh>
          </geometry>
        </visual>
        <self_collide>0</self_collide>
        <kinematic>0</kinematic>
        <gravity>1</gravity>
      </link>
      <joint name='torso_lift_joint' type='prismatic'>
        <child>torso_lift_link</child>
        <parent>base_footprint</parent>
        <axis>
          <xyz>0 0 1</xyz>
          <limit>
            <lower>0</lower>
            <upper>0.35</upper>
            <effort>2000</effort>
            <velocity>0.07</velocity>
          </limit>
          <dynamics>
            <damping>1000</damping>
            <friction>0</friction>
            <spring_reference>0</spring_reference>
            <spring_stiffness>0</spring_stiffness>
          </dynamics>
          <use_parent_model_frame>1</use_parent_model_frame>
        </axis>
      </joint>
      <link name='arm_1_link'>
        <pose frame=''>0.09305 0.014 0.7375 0 0 -1.5708</pose>
        <inertial>
          <pose frame=''>0.08169 0.01822 -0.01884 0 -0 0</pose>
          <mass>2.31325</mass>
          <inertia>
            <ixx>0.002694</ixx>
            <ixy>0.001157</ixy>
            <ixz>-0.001423</ixz>
            <iyy>0.007041</iyy>
            <iyz>-0.000312</iyz>
            <izz>0.007312</izz>
          </inertia>
        </inertial>
        <collision name='arm_1_link_collision'>
          <pose frame=''>0 0 0 0 -0 0</pose>
          <geometry>
            <mesh>
              <scale>1 1 1</scale>
              <uri>/home/fitter/tiago_public_ws/src/tiago_robot/tiago_description/meshes/arm/arm_1_collision.dae</uri>
            </mesh>
          </geometry>
          <surface>
            <contact>
              <ode/>
            </contact>
            <friction>
              <ode>
                <mu>0.9</mu>
                <mu2>0.9</mu2>
              </ode>
              <torsional>
                <ode/>
              </torsional>
            </friction>
            <bounce/>
          </surface>
          <max_contacts>10</max_contacts>
        </collision>
        <visual name='arm_1_link_visual'>
          <pose frame=''>0 0 0 0 -0 0</pose>
          <geometry>
            <mesh>
              <scale>1 1 1</scale>
              <uri>/home/fitter/tiago_public_ws/src/tiago_robot/tiago_description/meshes/arm/arm_1.stl</uri>
            </mesh>
          </geometry>
          <material>
            <script>
              <name>Gazebo/DarkGrey</name>
              <uri>file://media/materials/scripts/gazebo.material</uri>
            </script>
          </material>
        </visual>
        <velocity_decay/>
        <gravity>1</gravity>
        <velocity_decay/>
        <self_collide>0</self_collide>
        <kinematic>0</kinematic>
      </link>
      <joint name='arm_1_joint' type='revolute'>
        <child>arm_1_link</child>
        <parent>torso_lift_link</parent>
        <axis>
          <xyz>0 0 1</xyz>
          <limit>
            <lower>0</lower>
            <upper>2.74889</upper>
            <effort>39</effort>
            <velocity>2.7</velocity>
          </limit>
          <dynamics>
            <damping>1</damping>
            <friction>1</friction>
            <spring_reference>0</spring_reference>
            <spring_stiffness>0</spring_stiffness>
          </dynamics>
          <use_parent_model_frame>1</use_parent_model_frame>
        </axis>
        <physics>
          <ode>
            <implicit_spring_damper>1</implicit_spring_damper>
            <cfm_damping>1</cfm_damping>
            <limit>
              <cfm>0</cfm>
              <erp>0.2</erp>
            </limit>
          </ode>
        </physics>
      </joint>
      <link name='arm_2_link'>
        <pose frame=''>0.10955 -0.111 0.7065 1.5708 0 -1.5708</pose>
        <inertial>
          <pose frame=''>-0.03609 -6e-05 0.01649 0 -0 0</pose>
          <mass>1.10224</mass>
          <inertia>
            <ixx>0.001146</ixx>
            <ixy>1e-06</ixy>
            <ixz>0.000435</ixz>
            <iyy>0.002182</iyy>
            <iyz>-1e-06</iyz>
            <izz>0.002373</izz>
          </inertia>
        </inertial>
        <collision name='arm_2_link_collision'>
          <pose frame=''>0 0 0 0 -0 0</pose>
          <geometry>
            <mesh>
              <scale>1 1 1</scale>
              <uri>/home/fitter/tiago_public_ws/src/tiago_robot/tiago_description/meshes/arm/arm_2_collision.dae</uri>
            </mesh>
          </geometry>
          <surface>
            <contact>
              <ode/>
            </contact>
            <friction>
              <ode>
                <mu>0.9</mu>
                <mu2>0.9</mu2>
              </ode>
              <torsional>
                <ode/>
              </torsional>
            </friction>
            <bounce/>
          </surface>
          <max_contacts>10</max_contacts>
        </collision>
        <visual name='arm_2_link_visual'>
          <pose frame=''>0 0 0 0 -0 0</pose>
          <geometry>
            <mesh>
              <scale>1 1 1</scale>
              <uri>/home/fitter/tiago_public_ws/src/tiago_robot/tiago_description/meshes/arm/arm_2.stl</uri>
            </mesh>
          </geometry>
          <material>
            <script>
              <name>Gazebo/DarkGrey</name>
              <uri>file://media/materials/scripts/gazebo.material</uri>
            </script>
          </material>
        </visual>
        <gravity>1</gravity>
        <velocity_decay/>
        <self_collide>0</self_collide>
        <kinematic>0</kinematic>
      </link>
      <joint name='arm_2_joint' type='revolute'>
        <child>arm_2_link</child>
        <parent>arm_1_link</parent>
        <axis>
          <xyz>-1 0 0</xyz>
          <limit>
            <lower>-1.5708</lower>
            <upper>1.09083</upper>
            <effort>39</effort>
            <velocity>3.66</velocity>
          </limit>
          <dynamics>
            <damping>1</damping>
            <friction>1</friction>
            <spring_reference>0</spring_reference>
            <spring_stiffness>0</spring_stiffness>
          </dynamics>
          <use_parent_model_frame>1</use_parent_model_frame>
        </axis>
        <physics>
          <ode>
            <implicit_spring_damper>1</implicit_spring_damper>
            <cfm_damping>1</cfm_damping>
            <limit>
              <cfm>0</cfm>
              <erp>0.2</erp>
            </limit>
          </ode>
        </physics>
      </joint>
      <link name='arm_3_link'>
        <pose frame=''>0.10805 -0.2005 0.7065 2.3562 -1.57079 2.35621</pose>
        <inertial>
          <pose frame=''>0.00752 0.00244 0.12957 0 -0 0</pose>
          <mass>2.4246</mass>
          <inertia>
            <ixx>0.014418</ixx>
            <ixy>8.4e-05</ixy>
            <ixz>0.001143</ixz>
            <iyy>0.014788</iyy>
            <iyz>0.000642</iyz>
            <izz>0.00256</izz>
          </inertia>
        </inertial>
        <collision name='arm_3_link_collision'>
          <pose frame=''>0 0 0 0 -0 0</pose>
          <geometry>
            <mesh>
              <scale>1 1 1</scale>
              <uri>/home/fitter/tiago_public_ws/src/tiago_robot/tiago_description/meshes/arm/arm_3_collision.dae</uri>
            </mesh>
          </geometry>
          <surface>
            <contact>
              <ode/>
            </contact>
            <friction>
              <ode>
                <mu>0.9</mu>
                <mu2>0.9</mu2>
              </ode>
              <torsional>
                <ode/>
              </torsional>
            </friction>
            <bounce/>
          </surface>
          <max_contacts>10</max_contacts>
        </collision>
        <visual name='arm_3_link_visual'>
          <pose frame=''>0 0 0 0 -0 0</pose>
          <geometry>
            <mesh>
              <scale>1 1 1</scale>
              <uri>/home/fitter/tiago_public_ws/src/tiago_robot/tiago_description/meshes/arm/arm_3.stl</uri>
            </mesh>
          </geometry>
          <material>
            <script>
              <name>Gazebo/DarkGrey</name>
              <uri>file://media/materials/scripts/gazebo.material</uri>
            </script>
          </material>
        </visual>
        <gravity>1</gravity>
        <velocity_decay/>
        <self_collide>0</self_collide>
        <kinematic>0</kinematic>
      </link>
      <joint name='arm_3_joint' type='revolute'>
        <child>arm_3_link</child>
        <parent>arm_2_link</parent>
        <axis>
          <xyz>0 1 0</xyz>
          <limit>
            <lower>-3.53429</lower>
            <upper>1.5708</upper>
            <effort>17.86</effort>
            <velocity>4.58</velocity>
          </limit>
          <dynamics>
            <damping>1</damping>
            <friction>1</friction>
            <spring_reference>0</spring_reference>
            <spring_stiffness>0</spring_stiffness>
          </dynamics>
          <use_parent_model_frame>1</use_parent_model_frame>
        </axis>
        <physics>
          <ode>
            <implicit_spring_damper>1</implicit_spring_damper>
            <cfm_damping>1</cfm_damping>
            <limit>
              <cfm>0</cfm>
              <erp>0.2</erp>
            </limit>
          </ode>
        </physics>
      </joint>
      <link name='arm_4_link'>
        <pose frame=''>0.08105 -0.4225 0.6865 1.5708 -0 1.5708</pose>
        <inertial>
          <pose frame=''>0.07426 -0.01306 0.01549 0 -0 0</pose>
          <mass>1.45429</mass>
          <inertia>
            <ixx>0.001953</ixx>
            <ixy>-0.000596</ixy>
            <ixz>0.00088</ixz>
            <iyy>0.007097</iyy>
            <iyz>-0.000171</iyz>
            <izz>0.007405</izz>
          </inertia>
        </inertial>
        <collision name='arm_4_link_collision'>
          <pose frame=''>0 0 0 0 -0 0</pose>
          <geometry>
            <mesh>
              <scale>1 1 1</scale>
              <uri>/home/fitter/tiago_public_ws/src/tiago_robot/tiago_description/meshes/arm/arm_4_collision.dae</uri>
            </mesh>
          </geometry>
          <surface>
            <contact>
              <ode/>
            </contact>
            <friction>
              <ode>
                <mu>0.9</mu>
                <mu2>0.9</mu2>
              </ode>
              <torsional>
                <ode/>
              </torsional>
            </friction>
            <bounce/>
          </surface>
          <max_contacts>10</max_contacts>
        </collision>
        <visual name='arm_4_link_visual'>
          <pose frame=''>0 0 0 0 -0 0</pose>
          <geometry>
            <mesh>
              <scale>1 1 1</scale>
              <uri>/home/fitter/tiago_public_ws/src/tiago_robot/tiago_description/meshes/arm/arm_4.stl</uri>
            </mesh>
          </geometry>
          <material>
            <script>
              <name>Gazebo/DarkGrey</name>
              <uri>file://media/materials/scripts/gazebo.material</uri>
            </script>
          </material>
        </visual>
        <gravity>1</gravity>
        <velocity_decay/>
        <self_collide>0</self_collide>
        <kinematic>0</kinematic>
      </link>
      <joint name='arm_4_joint' type='revolute'>
        <child>arm_4_link</child>
        <parent>arm_3_link</parent>
        <axis>
          <xyz>1 0 0</xyz>
          <limit>
            <lower>-0.392699</lower>
            <upper>2.35619</upper>
            <effort>17.86</effort>
            <velocity>4.58</velocity>
          </limit>
          <dynamics>
            <damping>1</damping>
            <friction>1</friction>
            <spring_reference>0</spring_reference>
            <spring_stiffness>0</spring_stiffness>
          </dynamics>
          <use_parent_model_frame>1</use_parent_model_frame>
        </axis>
        <physics>
          <ode>
            <implicit_spring_damper>1</implicit_spring_damper>
            <cfm_damping>1</cfm_damping>
            <limit>
              <cfm>0</cfm>
              <erp>0.2</erp>
            </limit>
          </ode>
        </physics>
      </joint>
      <link name='arm_5_link'>
        <pose frame=''>0.10805 -0.5845 0.7065 1.5708 -0 0</pose>
        <inertial>
          <pose frame=''>3e-05 -0.00028 0.07831 0 -0 0</pose>
          <mass>1.07424</mass>
          <inertia>
            <ixx>0.00168</ixx>
            <ixy>1e-06</ixy>
            <ixz>-1.5e-05</ixz>
            <iyy>0.001603</iyy>
            <iyz>-1.9e-05</iyz>
            <izz>0.000404</izz>
          </inertia>
        </inertial>
        <collision name='arm_5_link_collision'>
          <pose frame=''>0 0 0 0 -0 0</pose>
          <geometry>
            <mesh>
              <scale>1 1 1</scale>
              <uri>/home/fitter/tiago_public_ws/src/tiago_robot/tiago_description/meshes/arm/arm_5_collision.dae</uri>
            </mesh>
          </geometry>
          <surface>
            <contact>
              <ode/>
            </contact>
            <friction>
              <ode>
                <mu>0.9</mu>
                <mu2>0.9</mu2>
              </ode>
              <torsional>
                <ode/>
              </torsional>
            </friction>
            <bounce/>
          </surface>
          <max_contacts>10</max_contacts>
        </collision>
        <visual name='arm_5_link_visual'>
          <pose frame=''>0 0 0 0 -0 0</pose>
          <geometry>
            <mesh>
              <scale>1 1 1</scale>
              <uri>/home/fitter/tiago_public_ws/src/tiago_robot/tiago_description/meshes/arm/arm_5.stl</uri>
            </mesh>
          </geometry>
          <material>
            <script>
              <uri>__default__</uri>
              <name>__default__</name>
            </script>
          </material>
        </visual>
        <gravity>1</gravity>
        <velocity_decay/>
        <self_collide>0</self_collide>
        <kinematic>0</kinematic>
      </link>
      <joint name='arm_5_joint' type='revolute'>
        <child>arm_5_link</child>
        <parent>arm_4_link</parent>
        <axis>
          <xyz>0 -1 0</xyz>
          <limit>
            <lower>-2.0944</lower>
            <upper>2.0944</upper>
            <effort>3</effort>
            <velocity>1.95</velocity>
          </limit>
          <dynamics>
            <damping>1</damping>
            <friction>1</friction>
            <spring_reference>0</spring_reference>
            <spring_stiffness>0</spring_stiffness>
          </dynamics>
          <use_parent_model_frame>1</use_parent_model_frame>
        </axis>
        <physics>
          <ode>
            <implicit_spring_damper>1</implicit_spring_damper>
            <cfm_damping>1</cfm_damping>
            <limit>
              <cfm>0</cfm>
              <erp>0.2</erp>
            </limit>
          </ode>
        </physics>
      </joint>
      <link name='arm_6_link'>
        <pose frame=''>0.10805 -0.7345 0.7065 0 0 -1.5708</pose>
        <inertial>
          <pose frame=''>0.00531 0.00021 2e-05 0 -0 0</pose>
          <mass>0.28722</mass>
          <inertia>
            <ixx>5.9e-05</ixx>
            <ixy>-0</ixy>
            <ixz>-0</ixz>
            <iyy>0.000106</iyy>
            <iyz>0</iyz>
            <izz>0.000126</izz>
          </inertia>
        </inertial>
        <collision name='arm_6_link_collision'>
          <pose frame=''>0 0 0 0 -0 0</pose>
          <geometry>
            <mesh>
              <scale>1 1 1</scale>
              <uri>/home/fitter/tiago_public_ws/src/tiago_robot/tiago_description/meshes/arm/arm_6_collision.dae</uri>
            </mesh>
          </geometry>
          <surface>
            <contact>
              <ode/>
            </contact>
            <friction>
              <ode>
                <mu>0.9</mu>
                <mu2>0.9</mu2>
              </ode>
              <torsional>
                <ode/>
              </torsional>
            </friction>
            <bounce/>
          </surface>
          <max_contacts>10</max_contacts>
        </collision>
        <visual name='arm_6_link_visual'>
          <pose frame=''>0 0 0 0 -0 0</pose>
          <geometry>
            <mesh>
              <scale>1 1 1</scale>
              <uri>/home/fitter/tiago_public_ws/src/tiago_robot/tiago_description/meshes/arm/arm_6.stl</uri>
            </mesh>
          </geometry>
          <material>
            <script>
              <uri>__default__</uri>
              <name>__default__</name>
            </script>
          </material>
        </visual>
        <gravity>1</gravity>
        <velocity_decay/>
        <self_collide>0</self_collide>
        <kinematic>0</kinematic>
      </link>
      <joint name='arm_6_joint' type='revolute'>
        <child>arm_6_link</child>
        <parent>arm_5_link</parent>
        <axis>
          <xyz>0 0 1</xyz>
          <limit>
            <lower>-1.5708</lower>
            <upper>1.5708</upper>
            <effort>6.6</effort>
            <velocity>1.76</velocity>
          </limit>
          <dynamics>
            <damping>1</damping>
            <friction>1</friction>
            <spring_reference>0</spring_reference>
            <spring_stiffness>0</spring_stiffness>
          </dynamics>
          <use_parent_model_frame>1</use_parent_model_frame>
        </axis>
        <physics>
          <ode>
            <implicit_spring_damper>1</implicit_spring_damper>
            <cfm_damping>1</cfm_damping>
            <limit>
              <cfm>0</cfm>
              <erp>0.2</erp>
            </limit>
          </ode>
        </physics>
      </joint>
      <link name='arm_7_link'>
        <pose frame=''>0.10805 -0.7345 0.7065 1.5708 -0 0</pose>
        <inertial>
          <pose frame=''>-0.000222 0.000206 0.078376 0 -0 0</pose>
          <mass>0.76221</mass>
          <inertia>
            <ixx>0.00140814</ixx>
            <ixy>4.5019e-05</ixy>
            <ixz>2.23289e-06</ixz>
            <iyy>0.00107713</iyy>
            <iyz>-2.99383e-06</iyz>
            <izz>0.000696041</izz>
          </inertia>
        </inertial>
        <collision name='arm_7_link_fixed_joint_lump__arm_tool_link_collision'>
          <pose frame=''>-0 0 0.047 0 -0 -1.5708</pose>
          <geometry>
            <cylinder>
              <length>0.005</length>
              <radius>0.005</radius>
            </cylinder>
          </geometry>
          <max_contacts>10</max_contacts>
          <surface>
            <contact>
              <ode/>
            </contact>
            <bounce/>
            <friction>
              <torsional>
                <ode/>
              </torsional>
              <ode/>
            </friction>
          </surface>
        </collision>
        <collision name='arm_7_link_fixed_joint_lump__gripper_link_collision_1'>
          <pose frame=''>-0 0 0.056 3.14159 -0 -1.5708</pose>
          <geometry>
            <mesh>
              <scale>1 1 1</scale>
              <uri>/home/fitter/tiago_public_ws/src/pal_gripper/pal_gripper_description/meshes/gripper_link_collision.stl</uri>
            </mesh>
          </geometry>
          <surface>
            <contact>
              <ode/>
            </contact>
            <friction>
              <ode/>
              <torsional>
                <ode/>
              </torsional>
            </friction>
            <bounce/>
          </surface>
          <max_contacts>10</max_contacts>
        </collision>
        <visual name='arm_7_link_fixed_joint_lump__arm_tool_link_visual'>
          <pose frame=''>-0 0 0.047 0 -0 -1.5708</pose>
          <geometry>
            <cylinder>
              <length>0.005</length>
              <radius>0.005</radius>
            </cylinder>
          </geometry>
        </visual>
        <visual name='arm_7_link_fixed_joint_lump__gripper_link_visual_1'>
          <pose frame=''>-0 0 0.056 3.14159 -0 -1.5708</pose>
          <geometry>
            <mesh>
              <scale>1 1 1</scale>
              <uri>/home/fitter/tiago_public_ws/src/pal_gripper/pal_gripper_description/meshes/gripper_link.stl</uri>
            </mesh>
          </geometry>
          <material>
            <script>
              <name>Gazebo/White</name>
              <uri>file://media/materials/scripts/gazebo.material</uri>
            </script>
          </material>
        </visual>
        <velocity_decay/>
        <gravity>1</gravity>
        <velocity_decay/>
        <self_collide>0</self_collide>
        <kinematic>0</kinematic>
      </link>
      <joint name='arm_7_joint' type='revolute'>
        <child>arm_7_link</child>
        <parent>arm_6_link</parent>
        <axis>
          <xyz>0 -1 0</xyz>
          <limit>
            <lower>-2.0944</lower>
            <upper>2.0944</upper>
            <effort>6.6</effort>
            <velocity>1.76</velocity>
          </limit>
          <dynamics>
            <damping>1</damping>
            <friction>1</friction>
            <spring_reference>0</spring_reference>
            <spring_stiffness>0</spring_stiffness>
          </dynamics>
          <use_parent_model_frame>1</use_parent_model_frame>
        </axis>
        <physics>
          <provide_feedback>1</provide_feedback>
          <ode>
            <provide_feedback>1</provide_feedback>
            <implicit_spring_damper>1</implicit_spring_damper>
            <cfm_damping>1</cfm_damping>
            <limit>
              <cfm>0</cfm>
              <erp>0.2</erp>
            </limit>
          </ode>
        </physics>
      </joint>
      <link name='gripper_left_finger_link'>
        <pose frame=''>0.10805 -0.7905 0.7065 -2.16534 1.57079 -0.594543</pose>
        <inertial>
          <pose frame=''>-0.00447 0.010766 -0.121013 0 -0 0</pose>
          <mass>0.10998</mass>
          <inertia>
            <ixx>0.000232</ixx>
            <ixy>-5e-06</ixy>
            <ixz>-3.2e-05</ixz>
            <iyy>0.000224</iyy>
            <iyz>3.6e-05</iyz>
            <izz>2.9e-05</izz>
          </inertia>
        </inertial>
        <collision name='gripper_left_finger_link_collision'>
          <pose frame=''>-0.005 0 -0.165 0 -0 3.1415</pose>
          <geometry>
            <box>
              <size>0.01 0.05 0.11</size>
            </box>
          </geometry>
          <surface>
            <contact>
              <ode>
                <kp>1e+06</kp>
                <kd>1</kd>
                <max_vel>1</max_vel>
                <min_depth>0.1</min_depth>
              </ode>
            </contact>
            <friction>
              <ode>
                <mu>1</mu>
                <mu2>1</mu2>
                <fdir1>0 0 0</fdir1>
              </ode>
              <torsional>
                <ode/>
              </torsional>
            </friction>
            <bounce/>
          </surface>
          <max_contacts>10</max_contacts>
        </collision>
        <visual name='gripper_left_finger_link_visual'>
          <pose frame=''>0 0 0 0 -0 3.1415</pose>
          <geometry>
            <mesh>
              <scale>1 1 1</scale>
              <uri>/home/fitter/tiago_public_ws/src/pal_gripper/pal_gripper_description/meshes/gripper_finger_link.stl</uri>
            </mesh>
          </geometry>
          <material>
            <script>
              <name>Gazebo/Black</name>
              <uri>file://media/materials/scripts/gazebo.material</uri>
            </script>
          </material>
        </visual>
        <velocity_decay/>
        <gravity>1</gravity>
        <velocity_decay/>
        <self_collide>0</self_collide>
        <kinematic>0</kinematic>
      </link>
      <joint name='gripper_left_finger_joint' type='prismatic'>
        <child>gripper_left_finger_link</child>
        <parent>arm_7_link</parent>
        <axis>
          <xyz>0 -0 1</xyz>
          <limit>
            <lower>0</lower>
            <upper>0.045</upper>
            <effort>16</effort>
            <velocity>0.05</velocity>
          </limit>
          <dynamics>
            <damping>80</damping>
            <friction>0</friction>
            <spring_reference>0</spring_reference>
            <spring_stiffness>0</spring_stiffness>
          </dynamics>
          <use_parent_model_frame>1</use_parent_model_frame>
        </axis>
        <physics>
          <provide_feedback>1</provide_feedback>
          <ode>
            <provide_feedback>1</provide_feedback>
            <implicit_spring_damper>1</implicit_spring_damper>
            <cfm_damping>1</cfm_damping>
            <limit>
              <cfm>0</cfm>
              <erp>0.2</erp>
            </limit>
          </ode>
        </physics>
      </joint>
      <link name='gripper_right_finger_link'>
        <pose frame=''>0.10805 -0.7905 0.7065 -2.16534 1.57079 -0.594543</pose>
        <inertial>
          <pose frame=''>-0.00447 0.010766 -0.121013 0 -0 0</pose>
          <mass>0.10998</mass>
          <inertia>
            <ixx>0.000232</ixx>
            <ixy>-5e-06</ixy>
            <ixz>-3.2e-05</ixz>
            <iyy>0.000224</iyy>
            <iyz>3.6e-05</iyz>
            <izz>2.9e-05</izz>
          </inertia>
        </inertial>
        <collision name='gripper_right_finger_link_collision'>
          <pose frame=''>0.005 0 -0.165 0 -0 3.1415</pose>
          <geometry>
            <box>
              <size>0.01 0.05 0.11</size>
            </box>
          </geometry>
          <surface>
            <contact>
              <ode>
                <kp>1e+06</kp>
                <kd>1</kd>
                <max_vel>1</max_vel>
                <min_depth>0.1</min_depth>
              </ode>
            </contact>
            <friction>
              <ode>
                <mu>1</mu>
                <mu2>1</mu2>
                <fdir1>0 0 0</fdir1>
              </ode>
              <torsional>
                <ode/>
              </torsional>
            </friction>
            <bounce/>
          </surface>
          <max_contacts>10</max_contacts>
        </collision>
        <visual name='gripper_right_finger_link_visual'>
          <pose frame=''>0 0 0 0 -0 3.1415</pose>
          <geometry>
            <mesh>
              <scale>1 1 1</scale>
              <uri>/home/fitter/tiago_public_ws/src/pal_gripper/pal_gripper_description/meshes/gripper_finger_link.stl</uri>
            </mesh>
          </geometry>
          <material>
            <script>
              <name>Gazebo/Black</name>
              <uri>file://media/materials/scripts/gazebo.material</uri>
            </script>
          </material>
        </visual>
        <velocity_decay/>
        <gravity>1</gravity>
        <velocity_decay/>
        <self_collide>0</self_collide>
        <kinematic>0</kinematic>
      </link>
      <joint name='gripper_right_finger_joint' type='prismatic'>
        <child>gripper_right_finger_link</child>
        <parent>arm_7_link</parent>
        <axis>
          <xyz>-0 0 -1</xyz>
          <limit>
            <lower>0</lower>
            <upper>0.045</upper>
            <effort>16</effort>
            <velocity>0.05</velocity>
          </limit>
          <dynamics>
            <damping>80</damping>
            <friction>0</friction>
            <spring_reference>0</spring_reference>
            <spring_stiffness>0</spring_stiffness>
          </dynamics>
          <use_parent_model_frame>1</use_parent_model_frame>
        </axis>
        <physics>
          <provide_feedback>1</provide_feedback>
          <ode>
            <provide_feedback>1</provide_feedback>
            <implicit_spring_damper>1</implicit_spring_damper>
            <cfm_damping>1</cfm_damping>
            <limit>
              <cfm>0</cfm>
              <erp>0.2</erp>
            </limit>
          </ode>
        </physics>
      </joint>
      <link name='head_1_link'>
        <pose frame=''>0.12 0 0.8885 0 -0 0</pose>
        <inertial>
          <pose frame=''>-0.00508 0.00237 0.07229 0 -0 0</pose>
          <mass>0.6222</mass>
          <inertia>
            <ixx>0.001192</ixx>
            <ixy>-7e-06</ixy>
            <ixz>9.6e-05</ixz>
            <iyy>0.001402</iyy>
            <iyz>4e-06</iyz>
            <izz>0.000889</izz>
          </inertia>
        </inertial>
        <collision name='head_1_link_collision'>
          <pose frame=''>0 0 0 0 -0 0</pose>
          <geometry>
            <mesh>
              <scale>1 1 1</scale>
              <uri>/home/fitter/tiago_public_ws/src/tiago_robot/tiago_description/meshes/head/head_1_collision.dae</uri>
            </mesh>
          </geometry>
          <surface>
            <contact>
              <ode/>
            </contact>
            <friction>
              <ode>
                <mu>0.9</mu>
                <mu2>0.9</mu2>
              </ode>
              <torsional>
                <ode/>
              </torsional>
            </friction>
            <bounce/>
          </surface>
          <max_contacts>10</max_contacts>
        </collision>
        <visual name='head_1_link_visual'>
          <pose frame=''>0 0 0 0 -0 0</pose>
          <geometry>
            <mesh>
              <scale>1 1 1</scale>
              <uri>/home/fitter/tiago_public_ws/src/tiago_robot/tiago_description/meshes/head/head_1.stl</uri>
            </mesh>
          </geometry>
          <material>
            <script>
              <uri>__default__</uri>
              <name>__default__</name>
            </script>
          </material>
        </visual>
        <gravity>1</gravity>
        <velocity_decay/>
        <self_collide>0</self_collide>
        <kinematic>0</kinematic>
      </link>
      <joint name='head_1_joint' type='revolute'>
        <child>head_1_link</child>
        <parent>torso_lift_link</parent>
        <axis>
          <xyz>0 0 1</xyz>
          <limit>
            <lower>-1.309</lower>
            <upper>1.309</upper>
            <effort>5.197</effort>
            <velocity>3</velocity>
          </limit>
          <dynamics>
            <damping>0.5</damping>
            <friction>1</friction>
            <spring_reference>0</spring_reference>
            <spring_stiffness>0</spring_stiffness>
          </dynamics>
          <use_parent_model_frame>1</use_parent_model_frame>
        </axis>
        <physics>
          <ode>
            <implicit_spring_damper>1</implicit_spring_damper>
            <cfm_damping>1</cfm_damping>
            <limit>
              <cfm>0</cfm>
              <erp>0.2</erp>
            </limit>
          </ode>
        </physics>
      </joint>
      <link name='head_2_link'>
        <pose frame=''>0.125 0 0.9865 1.5708 -0 0</pose>
        <inertial>
          <pose frame=''>0.055788 0.060977 1.1e-05 0 -0 0</pose>
          <mass>0.88593</mass>
          <inertia>
            <ixx>0.00476064</ixx>
            <ixy>0.000561581</ixy>
            <ixz>1.2081e-05</ixz>
            <iyy>0.00512284</iyy>
            <iyz>9.40226e-06</iyz>
            <izz>0.00346439</izz>
          </inertia>
        </inertial>
        <collision name='head_2_link_collision'>
          <pose frame=''>0 0 0 0 -0 0</pose>
          <geometry>
            <mesh>
              <scale>1 1 1</scale>
              <uri>/home/fitter/tiago_public_ws/src/tiago_robot/tiago_description/meshes/head/head_2_collision.dae</uri>
            </mesh>
          </geometry>
          <max_contacts>10</max_contacts>
          <surface>
            <contact>
              <ode/>
            </contact>
            <bounce/>
            <friction>
              <torsional>
                <ode/>
              </torsional>
              <ode/>
            </friction>
          </surface>
        </collision>
        <visual name='head_2_link_visual'>
          <pose frame=''>0 0 0 0 -0 0</pose>
          <geometry>
            <mesh>
              <scale>1 1 1</scale>
              <uri>/home/fitter/tiago_public_ws/src/tiago_robot/tiago_description/meshes/head/head_2.stl</uri>
            </mesh>
          </geometry>
        </visual>
        <gravity>1</gravity>
        <velocity_decay/>
        <self_collide>0</self_collide>
        <sensor name='xtion_frame_sensor' type='depth'>
          <always_on>1</always_on>
          <update_rate>30</update_rate>
          <camera name='__default__'>
            <horizontal_fov>1.01229</horizontal_fov>
            <image>
              <format>B8G8R8</format>
              <width>640</width>
              <height>480</height>
            </image>
            <clip>
              <near>0.3</near>
              <far>8</far>
            </clip>
          </camera>
          <plugin name='xtion_frame_controller' filename='libgazebo_ros_openni_kinect.so'>
            <alwaysOn>true</alwaysOn>
            <updateRate>30.0</updateRate>
            <cameraName>xtion</cameraName>
            <imageTopicName>rgb/image_raw</imageTopicName>
            <cameraInfoTopicName>rgb/camera_info</cameraInfoTopicName>
            <depthImageTopicName>depth_registered/image_raw</depthImageTopicName>
            <depthImageCameraInfoTopicName>depth_registered/camera_info</depthImageCameraInfoTopicName>
            <pointCloudTopicName>depth_registered/points</pointCloudTopicName>
            <frameName>xtion_rgb_optical_frame</frameName>
            <pointCloudCutoff>0.5</pointCloudCutoff>
            <pointCloudCutoffMax>8.0</pointCloudCutoffMax>
            <distortionK1>0.00000001</distortionK1>
            <distortionK2>0.00000001</distortionK2>
            <distortionK3>0.00000001</distortionK3>
            <distortionT1>0.00000001</distortionT1>
            <distortionT2>0.00000001</distortionT2>
            <robotNamespace>/</robotNamespace>
          </plugin>
          <pose frame=''>0.0908 0.08 -0.022 -1.5708 0 0</pose>
        </sensor>
        <kinematic>0</kinematic>
      </link>
      <joint name='head_2_joint' type='revolute'>
        <child>head_2_link</child>
        <parent>head_1_link</parent>
        <axis>
          <xyz>0 -1 0</xyz>
          <limit>
            <lower>-1.0472</lower>
            <upper>0.785398</upper>
            <effort>2.77</effort>
            <velocity>3</velocity>
          </limit>
          <dynamics>
            <damping>0.5</damping>
            <friction>1</friction>
            <spring_reference>0</spring_reference>
            <spring_stiffness>0</spring_stiffness>
          </dynamics>
          <use_parent_model_frame>1</use_parent_model_frame>
        </axis>
      </joint>
      <link name='wheel_left_link'>
        <pose frame=''>0 0.2022 0.0985 -1.5708 0 0</pose>
        <inertial>
          <pose frame=''>0 0 0.00207 0 -0 0</pose>
          <mass>1.82362</mass>
          <inertia>
            <ixx>0.00499743</ixx>
            <ixy>-4.464e-08</ixy>
            <ixz>-2.245e-08</ixz>
            <iyy>0.00499742</iyy>
            <iyz>1.64e-09</iyz>
            <izz>0.0083924</izz>
          </inertia>
        </inertial>
        <collision name='wheel_left_link_collision'>
          <pose frame=''>0 0 0 0 -0 0</pose>
          <geometry>
            <cylinder>
              <length>0.04</length>
              <radius>0.0985</radius>
            </cylinder>
          </geometry>
          <surface>
            <contact>
              <ode>
                <kp>1e+06</kp>
                <kd>100</kd>
                <max_vel>1</max_vel>
                <min_depth>0.003</min_depth>
              </ode>
            </contact>
            <friction>
              <ode>
                <mu>1</mu>
                <mu2>1</mu2>
                <fdir1>1 0 0</fdir1>
              </ode>
              <torsional>
                <ode/>
              </torsional>
            </friction>
            <bounce/>
          </surface>
          <max_contacts>10</max_contacts>
        </collision>
        <visual name='wheel_left_link_visual'>
          <pose frame=''>0 0 0 3.14159 -0 0</pose>
          <geometry>
            <mesh>
              <scale>1 1 1</scale>
              <uri>/home/fitter/tiago_public_ws/src/pmb2_robot/pmb2_description/meshes/wheels/wheel.stl</uri>
            </mesh>
          </geometry>
          <material>
            <script>
              <name>Gazebo/DarkGrey</name>
              <uri>file://media/materials/scripts/gazebo.material</uri>
            </script>
          </material>
        </visual>
        <gravity>1</gravity>
        <velocity_decay/>
        <self_collide>0</self_collide>
        <kinematic>0</kinematic>
      </link>
      <joint name='wheel_left_joint' type='revolute'>
        <child>wheel_left_link</child>
        <parent>base_footprint</parent>
        <axis>
          <xyz>0 1 0</xyz>
          <limit>
            <lower>-1e+16</lower>
            <upper>1e+16</upper>
          </limit>
          <dynamics>
            <spring_reference>0</spring_reference>
            <spring_stiffness>0</spring_stiffness>
          </dynamics>
          <use_parent_model_frame>1</use_parent_model_frame>
        </axis>
      </joint>
      <link name='wheel_right_link'>
        <pose frame=''>0 -0.2022 0.0985 -1.5708 0 0</pose>
        <inertial>
          <pose frame=''>0 0 -0.00207 0 -0 0</pose>
          <mass>1.82362</mass>
          <inertia>
            <ixx>0.00499743</ixx>
            <ixy>4.464e-08</ixy>
            <ixz>-2.245e-08</ixz>
            <iyy>0.00499742</iyy>
            <iyz>-1.64e-09</iyz>
            <izz>0.0083924</izz>
          </inertia>
        </inertial>
        <collision name='wheel_right_link_collision'>
          <pose frame=''>0 0 0 0 -0 0</pose>
          <geometry>
            <cylinder>
              <length>0.04</length>
              <radius>0.0985</radius>
            </cylinder>
          </geometry>
          <surface>
            <contact>
              <ode>
                <kp>1e+06</kp>
                <kd>100</kd>
                <max_vel>1</max_vel>
                <min_depth>0.003</min_depth>
              </ode>
            </contact>
            <friction>
              <ode>
                <mu>1</mu>
                <mu2>1</mu2>
                <fdir1>1 0 0</fdir1>
              </ode>
              <torsional>
                <ode/>
              </torsional>
            </friction>
            <bounce/>
          </surface>
          <max_contacts>10</max_contacts>
        </collision>
        <visual name='wheel_right_link_visual'>
          <pose frame=''>0 0 0 0 -0 0</pose>
          <geometry>
            <mesh>
              <scale>1 1 1</scale>
              <uri>/home/fitter/tiago_public_ws/src/pmb2_robot/pmb2_description/meshes/wheels/wheel.stl</uri>
            </mesh>
          </geometry>
          <material>
            <script>
              <name>Gazebo/DarkGrey</name>
              <uri>file://media/materials/scripts/gazebo.material</uri>
            </script>
          </material>
        </visual>
        <gravity>1</gravity>
        <velocity_decay/>
        <self_collide>0</self_collide>
        <kinematic>0</kinematic>
      </link>
      <joint name='wheel_right_joint' type='revolute'>
        <child>wheel_right_link</child>
        <parent>base_footprint</parent>
        <axis>
          <xyz>0 1 0</xyz>
          <limit>
            <lower>-1e+16</lower>
            <upper>1e+16</upper>
          </limit>
          <dynamics>
            <spring_reference>0</spring_reference>
            <spring_stiffness>0</spring_stiffness>
          </dynamics>
          <use_parent_model_frame>1</use_parent_model_frame>
        </axis>
      </joint>
      <plugin name='gazebo_ros_control' filename='libgazebo_ros_control.so'>
        <ns/>
        <robotSimType>pal_hardware_gazebo/PalHardwareGazebo</robotSimType>
        <robotNamespace/>
        <controlPeriod>0.001</controlPeriod>
      </plugin>
      <plugin name='gazebo_ros_p3d' filename='libgazebo_ros_p3d.so'>
        <topicName>ground_truth_odom</topicName>
        <alwaysOn>true</alwaysOn>
        <updateRate>100.0</updateRate>
        <robotNamespace>/</robotNamespace>
        <bodyName>base_footprint</bodyName>
        <xyzOffset>0 0 -0.0985</xyzOffset>
        <rpyOffset>0 -0 0</rpyOffset>
      </plugin>
      <static>0</static>
      <plugin name='gazebo_ros_odometry' filename='libgazebo_world_odometry.so'>
        <frameName>base_footprint</frameName>
        <topicName>floating_base_pose_simulated</topicName>
        <robotNamespace>/</robotNamespace>
      </plugin>
      <pose frame=''>0 0 0 0 -0 0</pose>
    </model>
    <model name='drill'>
      <link name='link'>
        <inertial>
          <pose frame=''>-0.00637 -0.008 0.13254 0 -0 0</pose>
          <inertia>
            <ixx>0.0133113</ixx>
            <ixy>-0.00030365</ixy>
            <ixz>-0.00034148</ixz>
            <iyy>0.0115766</iyy>
            <iyz>0.00088073</iyz>
            <izz>0.00378028</izz>
          </inertia>
          <mass>1.50252</mass>
        </inertial>
        <collision name='collision'>
          <pose frame=''>0 0 -0.09 0 -0 0</pose>
          <geometry>
            <mesh>
              <uri>model://cordless_drill/meshes/cordless_drill.stl</uri>
              <scale>1 1 1</scale>
            </mesh>
          </geometry>
          <max_contacts>10</max_contacts>
          <surface>
            <contact>
              <ode/>
            </contact>
            <bounce/>
            <friction>
              <torsional>
                <ode/>
              </torsional>
              <ode/>
            </friction>
          </surface>
        </collision>
        <visual name='visual'>
          <pose frame=''>0 0 -0.09 0 -0 0</pose>
          <geometry>
            <mesh>
              <uri>model://cordless_drill/meshes/cordless_drill.dae</uri>
              <scale>1 1 1</scale>
            </mesh>
          </geometry>
        </visual>
        <self_collide>0</self_collide>
        <kinematic>0</kinematic>
        <gravity>1</gravity>
      </link>
      <pose frame=''>0.504072 -0.029147 0 0 -0 0</pose>
    </model>
    <state world_name='default'>
      <sim_time>569 971000000</sim_time>
      <real_time>1180 244641590</real_time>
      <wall_time>1524042435 745947930</wall_time>
      <iterations>569971</iterations>
      <model name='aruco_cube'>
        <pose frame=''>0.53006 -0.299879 0.863732 -0.003876 0.001202 -2e-06</pose>
        <scale>1 1 1</scale>
        <link name='link'>
          <pose frame=''>0.53006 -0.299879 0.863732 -0.003876 0.001202 -2e-06</pose>
          <velocity>0 0 0 0 -0 0</velocity>
          <acceleration>0 0 0 -4e-06 2e-06 0</acceleration>
          <wrench>0 0 0 0 -0 0</wrench>
        </link>
      </model>
      <model name='drill'>
        <pose frame=''>0.645203 -0.043452 0.812932 4e-06 -4e-06 -0.47518</pose>
        <scale>1 1 1</scale>
        <link name='link'>
          <pose frame=''>0.645203 -0.043452 0.812932 4e-06 -4e-06 -0.47518</pose>
          <velocity>0 0 0 0 -0 0</velocity>
          <acceleration>-0.107282 2.32412 -0.915872 -2.93123 -0.813772 -1.94575</acceleration>
          <wrench>-0.161194 3.49204 -1.37612 0 -0 0</wrench>
        </link>
      </model>
      <model name='ground_plane'>
        <pose frame=''>0 0 0 0 -0 0</pose>
        <scale>1 1 1</scale>
        <link name='link'>
          <pose frame=''>0 0 0 0 -0 0</pose>
          <velocity>0 0 0 0 -0 0</velocity>
          <acceleration>0 0 0 0 -0 0</acceleration>
          <wrench>0 0 0 0 -0 0</wrench>
        </link>
      </model>
      <model name='table1'>
        <pose frame=''>0.88 0 0 0 -0 0</pose>
        <scale>1 1 1</scale>
        <link name='link'>
          <pose frame=''>0.88 0 0 0 -0 0</pose>
          <velocity>0 0 0 0 -0 0</velocity>
          <acceleration>0 0 0 0 -0 0</acceleration>
          <wrench>0 0 0 0 -0 0</wrench>
        </link>
      </model>
      <model name='tiago_steel'>
        <pose frame=''>-0.155 -0.002005 -0.003149 3.6e-05 0.001306 0.024825</pose>
        <scale>1 1 1</scale>
        <link name='arm_1_link'>
          <pose frame=''>-0.061176 0.0143 0.87836 -0.001339 0.000339 -1.34597</pose>
          <velocity>0.000227 5.5e-05 -1.2e-05 -4e-05 2.3e-05 -0.003784</velocity>
          <acceleration>0.375201 -0.154524 -0.017857 -2.4963 1.10156 2.43336</acceleration>
          <wrench>0.867933 -0.357452 -0.041308 0 -0 0</wrench>
        </link>
        <link name='arm_2_link'>
          <pose frame=''>-0.017266 -0.103873 0.847291 1.56458 1.33933 -1.35202</pose>
          <velocity>-0.00023 -9.5e-05 -7e-06 0.00025 -0.000756 -0.003655</velocity>
          <acceleration>0.038396 -0.072577 -0.036457 -1.19668 -1.23616 0.757847</acceleration>
          <wrench>0.042321 -0.079997 -0.040185 0 -0 0</wrench>
        </link>
        <link name='arm_3_link'>
          <pose frame=''>-0.014263 -0.124241 0.760177 0.045358 -0.227053 -1.55092</pose>
          <velocity>-0.000282 -4.1e-05 -2.3e-05 0.000101 3e-06 0.000174</velocity>
          <acceleration>-0.043058 -0.101894 -0.037645 2.80079 0.710766 1.53277</acceleration>
          <wrench>-0.104399 -0.247053 -0.091274 0 -0 0</wrench>
        </link>
        <link name='arm_4_link'>
          <pose frame=''>-0.030561 -0.155284 0.5384 -1.52618 0.140281 -1.53446</pose>
          <velocity>-0.000273 -1.6e-05 -2.2e-05 4.5e-05 -1e-05 0.0001</velocity>
          <acceleration>-0.00397 -0.023272 -0.047272 -1.7074 0.191246 2.7779</acceleration>
          <wrench>-0.005773 -0.033845 -0.068747 0 -0 0</wrench>
        </link>
        <link name='arm_5_link'>
          <pose frame=''>-0.008638 0.008654 0.542459 0.301254 -1.42387 -1.83878</pose>
          <velocity>-0.000289 -1.2e-05 -1.4e-05 5.5e-05 9.3e-05 8.9e-05</velocity>
          <acceleration>-0.045834 -0.021966 -0.018784 -1.57265 0.437838 -1.21881</acceleration>
          <wrench>-0.049237 -0.023597 -0.020178 0 -0 0</wrench>
        </link>
        <link name='arm_6_link'>
          <pose frame=''>-0.014035 0.157083 0.56343 0.94743 -1.49626 2.22305</pose>
          <velocity>-0.000299 -1.2e-05 -4e-06 -8e-05 0.000186 5.9e-05</velocity>
          <acceleration>-0.049083 -0.019093 -0.007561 0.708066 -0.447626 -2.64479</acceleration>
          <wrench>-0.014098 -0.005484 -0.002172 0 -0 0</wrench>
        </link>
        <link name='arm_7_link'>
          <pose frame=''>-0.014035 0.157083 0.563429 0.043566 -0.060492 -1.54322</pose>
          <velocity>-0.000298 -1e-05 -4e-06 -6.8e-05 0.00018 3.1e-05</velocity>
          <acceleration>-0.019684 -0.006199 -0.006778 -0.047814 -0.07645 0.096916</acceleration>
          <wrench>-0.015003 -0.004725 -0.005166 0 -0 0</wrench>
        </link>
        <link name='base_footprint'>
          <pose frame=''>-0.155 -0.002005 -0.003149 3.6e-05 0.001306 0.024825</pose>
          <velocity>-0.000532 -2e-05 -0.000318 -7.2e-05 0.000933 8.5e-05</velocity>
          <acceleration>-0.153521 0.002805 -0.766984 3.02247 1.36857 -3.05658</acceleration>
          <wrench>-6.66307 0.121757 -33.2883 0 -0 0</wrench>
        </link>
        <link name='gripper_left_finger_link'>
          <pose frame=''>0.028347 0.161754 0.621229 -3.08104 0.043476 -3.11137</pose>
          <velocity>-0.000293 -5e-06 -1.2e-05 -5.7e-05 0.000167 -1.8e-05</velocity>
          <acceleration>0.004942 0.00423 -0.02496 0.973165 0.745565 3.09078</acceleration>
          <wrench>0.000543 0.000465 -0.002745 0 -0 0</wrench>
        </link>
        <link name='gripper_right_finger_link'>
          <pose frame=''>-0.061503 0.159039 0.617318 -3.08104 0.043486 -3.11139</pose>
          <velocity>-0.000288 -9e-06 5e-06 -6.8e-05 0.000185 7.8e-05</velocity>
          <acceleration>0.015062 0.005522 0.007818 0.015237 0.828032 1.95537</acceleration>
          <wrench>0.001657 0.000607 0.00086 0 -0 0</wrench>
        </link>
        <link name='head_1_link'>
          <pose frame=''>-0.033687 0.000971 1.02934 3.5e-05 0.001307 0.024827</pose>
          <velocity>0.00026 5e-05 -3.8e-05 1.2e-05 -0.000422 -0.000158</velocity>
          <acceleration>0.922469 0.086076 -0.071598 1.08754 -0.719351 -0.990735</acceleration>
          <wrench>0.57396 0.053556 -0.044548 0 -0 0</wrench>
        </link>
        <link name='head_2_link'>
          <pose frame=''>-0.02856 0.001095 1.12733 1.57084 0.401307 0.024842</pose>
          <velocity>0.000237 4.8e-05 -1.7e-05 1.5e-05 -0.000422 -0.000163</velocity>
          <acceleration>0.909596 0.062804 0.032409 3.0267 -1.27055 0.734257</acceleration>
          <wrench>0.805839 0.05564 0.028712 0 -0 0</wrench>
        </link>
        <link name='torso_lift_link'>
          <pose frame=''>-0.215632 -0.003547 1.02957 3.7e-05 0.001309 0.024827</pose>
          <velocity>0.000344 5.6e-05 9.7e-05 -7.8e-05 0.000759 4.8e-05</velocity>
          <acceleration>0.881697 0.088699 0.122542 -0.133188 1.43543 0.030268</acceleration>
          <wrench>6.1119 0.61486 0.849458 0 -0 0</wrench>
        </link>
        <link name='wheel_left_link'>
          <pose frame=''>-0.159891 0.200133 0.095358 1.57018 -1.51879 -3.11615</pose>
          <velocity>-0.000381 -1.2e-05 -0.000336 0.000126 -0.003869 3.8e-05</velocity>
          <acceleration>-0.297658 -0.00984 -0.807853 -3.09597 -1.33802 -3.06172</acceleration>
          <wrench>-0.542815 -0.017944 -1.47322 0 -0 0</wrench>
        </link>
        <link name='wheel_right_link'>
          <pose frame=''>-0.149853 -0.204143 0.095343 -1.57015 -1.52128 0.024174</pose>
          <velocity>-0.000366 -1.2e-05 -0.000311 0.000122 -0.003715 3.4e-05</velocity>
          <acceleration>-0.278511 -0.009318 -0.77144 -3.09878 -1.42952 -3.06975</acceleration>
          <wrench>-0.507899 -0.016992 -1.40681 0 -0 0</wrench>
        </link>
      </model>
      <light name='light1'>
        <pose frame=''>-2 0 4 0 -0 0</pose>
      </light>
    </state>
  </world>
</sdf>
